Workbook

Sheet 题库数据
A4: 题号 | B4: 题目 | C4: 选项A | D4: 选项B | E4: 选项C | F4: 选项D | G4: 选项E | H4: 选项F | I4: 你的选择 | J4: 正确答案_数据 | K4: 解析_数据 | L4: 是否正确 | M4: 正确选项 | N4: 解析显示
A5: 1 | B5: 一家公司有一个托管在 AWS 上的网站该网站位于应用程序负载均衡器(ALB)的后面,该应用程序负载均衡器(ALB)配置为分别处理 HTTP 和 HTTPS.该公司希望将所有请求转发到该网站,以便这些请求将使用 HTTPS.什么解决方案架构师应该做些什么来满足这个要求? | C5: 更新 ALB 的网络 ACL 以仅接受 HTTPS 流量 | D5: 创建一个规则,将 URL 中的 HTTP 替换为 HTTPS. | E5: 在 ALB 上创建一个监听器规则,将 HTTP 流量重定向到 HTTPS. | F5: 将 ALB 替换为配置为使用服务器名称指示(SNI)的网络负载均衡器. | I5: C | J5: C | K5: Cant be implemented on Lambda because the timeout for Lambda is 15mins and the Job takes 60minutes to complete | L5: ✅正确 | M5: C - 在 ALB 上创建一个监听器规则，将 HTTP 流量重定向到 HTTPS | N5: Cant be implemented on Lambda because the timeout for Lambda is 15mins and the Job takes 60minutes to complete
A6: 2 | B6: 一家公司正在 AWS 上开发一个两层 Web 应用程序,该公司的开发人员已将该应用程序部署在直接连接到后端 Amazon RDS 数据库的 Amazon EC2 实例上.该公司不得在应用程序中硬编码数据库凭证.该公司还必须实施定期自动轮换数据库凭据的解决方案.哪种解决方案能够以最少的运营开销满足这些要求? | C6: 将数据库凭证存储在实例元数据中.使用 Amazon EventBridge (Amazon CloudWatch Events)规则运行计划的 AWS Lambda 函数,该函数同时更新 RDS 凭证和实例元数据. | D6: 将数据库凭证存储在加密 Amazon S3 存储桶中的配置文件中.使用 Amazon EventBridge (Amazon CloudWatch Events)规则运行计划的 AWS Lambda 函数,该函数同时更新 RDS 凭证和配置文件中的凭证.使用 S3 版本控制确保能够回退到以前的值. | E6: 将数据库凭证作为秘密存储在 AWS Secrets Manager 中.打开秘密的自动轮换.将所需的权限附加到EC2 角色以授予对秘密的访问权限. | F6: 将数据库凭证作为加密参数存储在 AWS Systems Manager Parameter Store 中.为加密参数启用自动轮换.将所需权限附加到 EC2 角色以授予对加密参数的访问权限. | J6: C | K6: AWS Secrets Manager 是比 SSM Parameter store 更新的服务. https://docs.aws.amazon.com/secretsmanager/latest/userguide/create_database_secret.html | N6: AWS Secrets Manager 是比 SSM Parameter store 更新的服务. https://docs.aws.amazon.com/secretsmanager/latest/userguide/create_database_secret.html
A7: 3 | B7: 一家公司正在向 AWS 部署一个新的公共 Web 应用程序.该应用程序将在 Application Load Balancer (ALB)之后运行,该应用程序需要在边缘使用由外部证书颁发机构颁发的 SSL/TLS 证书进行加密(CA).证书必须在证书到期之前每年轮换.解决方案架构师应该做什么来满足这些要求? | C7: 使用 AWS Certificate Manager (ACM) 颁发 SSL/TLS 证书.将证书应用到 ALB.使用托管续订功能自动轮换证书. | D7: 使用 AWS Certificate Manager (ACM)颁发 SSL/TLS 证书.从证书中导入密钥材料.将证书应用到 ALB.使用托管续订功能自动轮换证书. | E7: 使用 AWS Certificate Manager (ACM) 私有证书颁发机构从根 CA 颁发 SSL/TLS 证书.将证书应用到 ALB.使用托管续订功能自动轮换证书. | F7: 使用 AWS Certificate Manager (ACM) 导入 SSL/TLS 证书.将证书应用到 ALB.使用 Amazon EventBridge (Amazon CloudWatch Events)在证书即将到期时发送通知.手动轮换证书. | J7: D | K7: It's a third-party certificate, hence AWS cannot manage renewal automatically. The closest thing you can do is to send a notification to renew the 3rd party certificate. | N7: It's a third-party certificate, hence AWS cannot manage renewal automatically. The closest thing you can do is to send a notification to renew the 3rd party certificate.
A8: 4 | B8: 一家公司在 AWS 上运行其基础设施,并拥有700.000 名注册用户,用于 res 文档管理应用程序,该公司打算创建一个将大型 pdf 文件转换为 jpg Imago 文件的产品 .. pdf 文件的平均大小为5 MB.公司需要存储原始文件和转换后的文件,解决方案架构师必须设计一个可扩展的解决方案,以适应随着时间的推移而迅速增长的需求.哪种解决方案最经济高效地满足这些要求? | C8: 将 pdf 文件保存到 Amazon S3.配置 S3 PUT 事件以调用 AWS Lambda 函数将文件转换为 jpg 格式并将它们存储回 Amazon S3. | D8: 将 pdf 文件保存到 Amazon DynamoDB.使用 DynamoDB Streams 功能调用 AWS Lambda 函数将文件转换为 jpg 格式并将它们存储在 DynamoDB 中. | E8: 将 .pdf 文件上传到包含 Amazon EC2 实例的 AWS Elastic Beanstalk 应用程序.Amazon Elastic Block Store (Amazon EBS) 存储和 Auto Scaling 组.在 EC2 实例中使用程序将文件转换为 jpg 格式保存.EBS 商店中的 pdf 文件和 .jpg 文件. | F8: 将 .pdf 文件上传到包含 Amazon EC2 实例.Amazon Elastic File System (Amazon EFS) 存储和 Auto Scaling 组的 AWS Elastic Beanstalk 应用程序.使用 EC2 实例中的程序将文件转换为 jpg 格式保存EBS 商店中的 pdf 文件和 jpg 文件. | J8: A | K8: This solution will meet the company's requirements in a cost-effective manner because it uses a serverless architecture with AWS Lambda to convert the files and store them in S3. The Lambda function will automatically scale to meet the demand for file conversions and S3 will automatically scale to store the original and converted files as needed.该解决方案将以经济高效的方式满足公司的要求,因为它使用了带有AWS Lambda的无服务器架构来转换文件并将其存储在S3中。Lambda功能将自动缩放以满足文件转换的需求,S3将根据需要自动缩放以存储原始文件和转换后的文件。 | N8: This solution will meet the company's requirements in a cost-effective manner because it uses a serverless architecture with AWS Lambda to convert the files and store them in S3. The Lambda function will automatically scale to meet the demand for file conversions and S3 will automatically scale to store the original and converted files as needed.该解决方案将以经济高效的方式满足公司的要求,因为它使用了带有AWS Lambda的无服务器架构来转换文件并将其存储在S3中。Lambda功能将自动缩放以满足文件转换的需求,S3将根据需要自动缩放以存储原始文件和转换后的文件。
A9: 5 | B9: 一家公司在本地运行的 Windows 文件服务器上拥有超过5 TB 的文件数据用户和应用程序每天与数据进行交互该公司正在将其 Windows 工作负载转移到 AWS.随着公司继续这一过程,该公司需要访问以最小的延迟连接到AWS 和本地文件存储.公司需要一种解决方案,最大限度地减少运营开销,并且不需要对现有文件访问模式进行重大更改.公司使用 AWS Site-to-Site VPN 连接来连接到 AWS.解决方案架构师应该怎么做才能满足这些要求? | C9: 在 AWS 上部署和配置 Amazon FSx for Windows File Server.将本地文件数据移动到 FSx for Windows File Server.重新配置工作负载以在 AWS 上使用 FSx for Windows File Server. | D9: 在本地部署和配置 Amazon S3 文件网关.将本地文件数据移动到 S3 文件网关,重新配置本地工作负载和云工作负载以使用 S3 文件网关 | E9: 在本地部署和配置 Amazon S3 文件网关.将本地文件数据移动到 Amazon S3.重新配置工作负载以直接使用 Amazon S3 或 S3 文件网关,具体取决于每个工作负载的位置. | F9: 在 AWS 上部署和配置 Amazon FSx for Windows File Server.在本地部署和配置 Amazon FSx 文件网关.将本地文件数据移动到 FSx 文件网关.配置云工作负载以使用 FSx for Windows File Server AWS.配置本地工作负载以使用 FSx 文件网关. | J9: D
A10: 6 | B10: 一家医院最近使用Amazon API Gateway 和AWS Lambda 部署了一个RESTful API.该医院使用API Gateway 和Lambda 上传PDF 格式和JPEG 格式的报告.医院需要修改Lambda 代码以识别受保护的健康信息(PHI)在报告中.哪种解决方案将以最少的运营开销满足这些要求? | C10: 使用现有的 Python 库从报告中提取文本并从提取的文本中识别 PHI. | D10: 使用 Amazon Textract 从报告中提取文本.使用 Amazon SageMaker 从提取的文本中识别 PHI. | E10: 使用 Amazon Textract 从报告中提取文本.使用 Amazon Comprehend Medical 从提取的文本中识别 PHI. | F10: 使用 Amazon Rekognition 从报告中提取文本.使用 Amazon Comprehend Medical 从提取的文本中识别 PHI. | J10: C | K10: Textract and Comprehend 符合 HIPPA.https://aws.amazon.com/blogs/machine-learning/amazon-textract-is-now-hipaaeligible/ | N10: Textract and Comprehend 符合 HIPPA.https://aws.amazon.com/blogs/machine-learning/amazon-textract-is-now-hipaaeligible/
A11: 7 | B11: 一家公司有一个应用程序生成大量文件,每个文件大小约为5 MB.这些文件存储在 Amazon S3 中.公司政策要求文件存储 4年才能删除始终可立即访问需要,因为文件包含不易复制的关键业务数据.文件在对象创建的前30天内经常访问,但在前30天后很少访问哪种存储解决方案最具成本效益? | C11: 创建一个S3存储桶生命周期策略,在创建对象后30天内将文件从S3 Standard移动到S3 Glacier。在创建对象4年后删除文件 | D11: 创建一个S3存储桶生命周期策略,在创建对象后30天内将文件从S3 Standard移动到S3 One Zone Un频繁访问(S3 One Zone IA)。在创建对象4年后删除文件 | E11: 创建一个S3存储桶生命周期策略,在创建对象后30天内将文件从S3 Standard移动到S3 Standard Infrequent Access (S3 Standard IA)。在创建对象4年后删除文件。 | F11: 创建 S3 存储桶生命周期策略,在对象创建后 30 天将文件从S3 标准移动到 S3 标准-不频繁访问(S3 标准-IA).在对象装箱 4年后将文件移动到 S3 Glacier. | J11: C | K11: 始终需要立即访问,因为文件包含关键业务数据 | N11: 始终需要立即访问,因为文件包含关键业务数据
A12: 8 | B12: 一家公司在多个 Amazon EC2 实例上托管应用程序,应用程序处理来自 Amazon SQS 队列的消息写入 Amazon RDS 表并从队列中删除消息在 RDS 表中偶尔发现重复记录.SQS 队列没有包含任何重复的消息.解决方案架构师应该怎么做才能确保消息只被处理一次? | C12: 使用 CreateQueue API 调用创建新队列 | D12: 使用 Add Permission API 调用添加适当的权限 | E12: 使用 ReceiveMessage API 调用设置适当的等待时间 | F12: 使用 ChangeMessageVisibility APi 调用来增加可见性超时 | J12: D | K12: 可见性超时在 Amazon SQS 返回消息时开始.在此期间,消费者会处理并删除消息.但是,如果消费者在删除消息之前失败,并且您的系统在可见性超时到期,该消息对其他消费者可见,并再次收到该消息.如果一条消息必须只接收一次,您的消费者应在可见性超时期限内将其删除.https://docs.aws.amazon.com/AWSSimpleQueueService/latest/SQSDeveloperGuide/sqs-visibilitytimeout.html 关键字:SQS 队列写入 Amazon RDS 由此,选项 D 最佳套件 &其他选项排除[选项A-您不能在现有队列中再插入一个队列;选项 B-only Permission & Option C-Only Retrieves Messages] FIF O 队列旨在从不引入重复消息.但是,您的消息生产者可能会在某些情况下引入重复消息:例如,如果生产者发送消息,没有收到响应,然后重新发送消息相同的消息.Amazon SQS API 提供重复数据删除功能,可防止您的消息生产者发送重复数据.消息生产者引入的任何重复数据都会在5分钟的重复数据删除间隔内删除.对于标准队列,您可能偶尔会收到消息的重复副本(至少一次传递).如果使用标准队列,则必须将应用程序设计为幂等的(即,在多次处理同一消息时,它们不得受到不利影响). | N12: 可见性超时在 Amazon SQS 返回消息时开始.在此期间,消费者会处理并删除消息.但是,如果消费者在删除消息之前失败,并且您的系统在可见性超时到期,该消息对其他消费者可见,并再次收到该消息.如果一条消息必须只接收一次,您的消费者应在可见性超时期限内将其删除.https://docs.aws.amazon.com/AWSSimpleQueueService/latest/SQSDeveloperGuide/sqs-visibilitytimeout.html 关键字:SQS 队列写入 Amazon RDS 由此,选项 D 最佳套件 &其他选项排除[选项A-您不能在现有队列中再插入一个队列;选项 B-only Permission & Option C-Only Retrieves Messages] FIF O 队列旨在从不引入重复消息.但是,您的消息生产者可能会在某些情况下引入重复消息:例如,如果生产者发送消息,没有收到响应,然后重新发送消息相同的消息.Amazon SQS API 提供重复数据删除功能,可防止您的消息生产者发送重复数据.消息生产者引入的任何重复数据都会在5分钟的重复数据删除间隔内删除.对于标准队列,您可能偶尔会收到消息的重复副本(至少一次传递).如果使用标准队列,则必须将应用程序设计为幂等的(即,在多次处理同一消息时,它们不得受到不利影响).
A13: 9 | B13: 一位解决方案架构师正在设计一种新的混合架构,以将公司的本地基础设施扩展到 AWS.公司需要与 AWS区域保持一致的低延迟的高可用性连接.公司需要最大限度地降低成本并愿意接受如果主连接失败,则流量会变慢.解决方案架构师应该怎么做才能满足这些要求? | C13: 提供与区域的 AWS Direct Connect 连接.如果主要 Direct Connect 连接失败,提供 VPN 连接作为备份. | D13: 为专用连接提供到区域的 VPN隧道连接.为专用连接提供第二条 VPN 隧道,并在主 VPN 连接失败时作为备用. | E13: 提供与区域的 AWS Direct Connect 连接.如果主要 Direct Connect 连接失败,则提供与同一区域的第二个 Direct Connect 连接作为备份. | F13: 为区域提供 AWS Direct Connect 连接.如果主要 Direct Connect 连接失败,则使用 AWS CLI 中的 Direct Connect 故障转移属性自动创建备份连接. | J13: A | K13: “在某些情况下,仅此连接是不够的,保证备用连接作为DX的备份总是更好.有多种选择,但使用 AWS Site-To-Site VPN 实施它是一项真正的成本- 可用于降低成本的有效解决方案,或者同时等待第二个DX的设置."https://www.proud2becloud.com/hybridcloud-networking-backup-aws-direct-connect-network-connection-with-aws-site-to-site-vpn/ | N13: “在某些情况下,仅此连接是不够的,保证备用连接作为DX的备份总是更好.有多种选择,但使用 AWS Site-To-Site VPN 实施它是一项真正的成本- 可用于降低成本的有效解决方案,或者同时等待第二个DX的设置."https://www.proud2becloud.com/hybridcloud-networking-backup-aws-direct-connect-network-connection-with-aws-site-to-site-vpn/
A14: 10 | B14: 一家公司正在 Application Load Balancer 后面的 Amazon EC2 实例上运行关键业务 Web 应用程序.EC2 实例位于 Auto Scaling 组中.该应用程序使用部署在单个可用区中的 Amazon Aurora PostgreSQL 数据库.公司希望应用程序具有高可用性,停机时间最短,数据丢失最少.哪种解决方案能够以最少的运营工作满足这些要求? | C14: 将 EC2 实例放置在不同的 AWS 区域中.使用 Amazon Route 53 运行状況检查来重定向流量.使用 Aurora PostgreSQL 跨区域复制. | D14: 将 Auto Scaling 组配置为使用多个可用区.将数据库配置为多可用区,为数据库配置 Amazon RDS 代理实例. | E14: 将 Auto Scaling 组配置为使用一个可用区.生成数据库的每小时快照.在发生故障时从快照中恢复数据库. | F14: 将 Auto Scaling 组配置为使用多个 AWS 区域.将数据从应用程序写入 Amazon S3.使用 S3 事件通知启动 AWS Lambda 函数以将数据写入数据库. | J14: B | K14: 用于 Aurora 的 RDS 代理 https://docs.aws.amazon.com/AmazonRDS/latest/AuroraUserGuide/rds-proxy.html | N14: 用于 Aurora 的 RDS 代理 https://docs.aws.amazon.com/AmazonRDS/latest/AuroraUserGuide/rds-proxy.html
A15: 11 | B15: 公司的 HTTP 应用程序位于网络负载均衡器(NLB)的后面.NLB 的目标组配置为使用 Amazon EC2 Auto Scaling 组,该组具有多个运行 Web 服务的 EC2 实例.公司注意到 NLB 未检测到 HTTP应用程序的错误.这些错误需要手动重新启动运行 Web 服务的 EC2 实例.公司需要在不编写自定义脚本或代码的情况下提高应用程序的可用性.解决方案架构师应该如何满足这些要求? | C15: 在 NLB 上启用 HTTP 健康检查.提供公司应用程序的 URL. | D15: 向EC2实例添加一个cron作业,每分钟检查一次本地应用程序的日志,如果检测到HTTP错误,应用程序将重新启动. | E15: 将 NLB 替换为 Application Load Balancer.通过提供公司应用程序的 URL 来启用 HTTP 运行状况检查.配置 Auto Scaling 操作以替换运行状况不佳的实例. | F15: 创建监控 NLB 的 UnhealthyHostCount 指标的 Amazon Cloud Watch 警报.配置 Auto Scaling 操作以在警报处于 ALARM 状态时替换不健康的实例. | J15: C | K15: NLB 工作在第 4层,因此不支持 HTTP/HTTPS.替代 ALB 是最佳选择. | N15: NLB 工作在第 4层,因此不支持 HTTP/HTTPS.替代 ALB 是最佳选择.
A16: 12 | B16: 一家公司运行一个购物应用程序,该应用程序使用 Amazon DynamoDB 存储客户信息.在数据损坏的情况下,解决方案架构师需要设计一个满足15分钟恢复点目标(RPO)和恢复时间目标(RTO)的解决方案)1小时.解决方案架构师应该推荐什么来满足这些要求? | C16: 配置 DynamoDB 全局表.对于 RPO 恢复,将应用程序指向不同的 AWS 区域. | D16: 配置 DynamoDB 时间点恢复,对于 RPO恢复,恢复到所需的时间点. | E16: 每天将 DynamoDB 数据导出到 Amazon S3 Glacier.对于 RPO 恢复,将数据从 S3 Glacier 导入到 DynamoDB. | F16: 每 15 分钟为 DynamoDB 表安排 Amazon Elastic Block Store (Amazon EBS) 快照.对于 RPO 恢复,使用 EBS 快照还原 DynamoDB 表. | J16: B | K16: A - DynamoDB 全局表提供多区域和多活动数据库,但它在“数据损坏的情况下“无效.在这种情况下,您需要备份,此解决方案无效. B-Point in Time Recovery 被设计为连续备份,可以快速恢复,它完美地涵盖了RPO,可能还有 RTO. https://docs.aws.amazon.com/amazondynamodb/latest/developerguide/PointInTimeRecovery.html C - 每日导出不会涵盖 15分钟的RPO. D - DynamoDB 是无服务器的. | N16: A - DynamoDB 全局表提供多区域和多活动数据库,但它在“数据损坏的情况下“无效.在这种情况下,您需要备份,此解决方案无效. B-Point in Time Recovery 被设计为连续备份,可以快速恢复,它完美地涵盖了RPO,可能还有 RTO. https://docs.aws.amazon.com/amazondynamodb/latest/developerguide/PointInTimeRecovery.html C - 每日导出不会涵盖 15分钟的RPO. D - DynamoDB 是无服务器的.
A17: 13 | B17: 一家公司运行的照片处理应用程序需要经常从位于同一 AWS 区域的 Amazon S3 存储桶上传和下载图片,一位解决方案架构师注意到数据传输费用的成本增加,需要实施一种解决方案来减少这些成本.解决方案架构师如何满足这一要求? | C17: 将 Amazon API Gateway 部署到公有子网并调整路由表以通过它路由 S3 调用. | D17: 将 NAT 网关部署到公共子网中,并附加一个允许访问S3 存储桶的端点策略. | E17: 将应用程序部署到公共子网中,并允许其通过互联网网关路由以访问S3 存储桶 | F17: 将 S3 VPC 网关终端节点部署到VPC中,并附加一个终端节点策略以允许访问S3 存储桶. | J17: D | K17: 为了降低成本,去掉了NAT 网关,VPC 端点到 S3. | N17: 为了降低成本,去掉了NAT 网关,VPC 端点到 S3.
A18: 14 | B18: 一家公司最近在私有子网中的 Amazon EC2 上启动了基于 Linux 的应用程序实例,并在 VPC的公共子网中的 Amazon EC2 实例上启动了基于 Linux 的堡垒主机.解决方案架构师需要从本地连接网络,通过公司与堡垒主机和应用程序服务器的互联网连接.解决方案架构师必须确保所有 EC2 实例的安全组都允许该访问.解决方案架构师应采取哪些步骤组合来满足这些要求?(选择两个) | C18: 将堡垒主机的当前安全组替换为仅允许来自应用程序实例的入站访问的安全组 | D18: 将堡垒主机的当前安全组替换为只允许公司内部IP范围的入站访问的安全组 | E18: 将堡垒主机的当前安全组替换为只允许公司外部IP范围入站访问的安全组 | F18: 将应用程序实例的当前安全组替换为仅允许从堡垒主机的私有IP地址进行入站 SSH 访问的安全组 | G18: 将应用程序实例的当前安全组替换为仅允许从堡垒主机的公共IP 地址进行入站 SSH 访问的安全组 | J18: C,D | K18: 选项C(仅允许来自外部 IP的访问)和 D(允许来自堡垒主机的私有 IP的入站 SSH) . https://digitalcloud.training/sshinto-ec2-in-private-subnet/ | N18: 选项C(仅允许来自外部 IP的访问)和 D(允许来自堡垒主机的私有 IP的入站 SSH) . https://digitalcloud.training/sshinto-ec2-in-private-subnet/
A19: 15 | B19: 一位解决方案架构师正在设计一个两层 Web 应用程序.该应用程序由托管在公共子网中的 Amazon EC2 上的面向公众的 Web 层组成.数据库层由在私有子网中的 Amazon EC2 上运行的 Microsoft SQL Server 组成.公司的高优先级.在这种情况下应该如何配置安全组? (选择两个) | C19: 将 Web 层的安全组配置为允许来自 0.0.0.0/0 的端口 443 上的入站流量. | D19: 将 Web 层的安全组配置为允许来自 0.0.0.0/0 的端口 443 上的出站流量. | E19: 配置数据库层的安全组以允许来自 Web 层安全组的端口 1433 上的入站流量. | F19: 配置数据库层的安全组以允许端口 443 和 1433 上的出站流量到 Web 层的安全组. | G19: 配置数据库层的安全组以允许来自 Web 层安全组的端口 443 和 1433 上的入站流量. | J19: A,C | K19: 公共子网上的 EC2 Web+私有子网上的EC2 SQL+安全性是高优先级.因此,选项A 允许来自任何地方的 HTTPS.加上选项C 以允许来自 Web 实例的 SQL 连接, | N19: 公共子网上的 EC2 Web+私有子网上的EC2 SQL+安全性是高优先级.因此,选项A 允许来自任何地方的 HTTPS.加上选项C 以允许来自 Web 实例的 SQL 连接,
A20: 16 | B20: 一家公司希望将多层应用程序从本地迁移到 AWS 云以提高应用程序的性能.该应用程序由通过 RESTful 服务相互通信的应用程序层组成.当一层过载时,事务将被丢弃.解决方案架构师必须设计一个解决方案来解决这些问题并使应用程序现代化.哪个解决方案满足这些要求并且最有效地运行? | C20: 使用 Amazon API Gateway 并将事务定向到 AWS Lambda 函数作为应用程序层.使用 Amazon Simple Queue Service (Amazon SQS)作为应用程序服务之间的通信层. | D20: 使用 Amazon CloudWatch 指标分析应用程序性能历史,以确定服务器在性能故障期间的峰值利用率.增加应用程序服务器的Amazon EC2 实例的大小以满足峰值要求. | E20: 使用 Amazon Simple Notification Service (Amazon SNS)处理 Auto Scaling 组中 Amazon EC2 上运行的应用程序服务器之间的消息传递.使用 Amazon CloudWatch 监控 SNS 队列长度并根据需要进行扩展和缩减. | F20: 使用 Amazon Simple Queue Service (Amazon SQS)处理 Auto Scaling 组中 Amazon EC2 上运行的应用程序服务器之间的消息传递.使用 Amazon CloudWatch 监控 SQS 队列长度并在检测到通信故障时向上扩展. | J20: A | K20: https://aws.amazon.com/getting-started/hands-on/build-serverless-web-app-lambda-apigateway-s3-dynamodbcognito/module-4/ | N20: https://aws.amazon.com/getting-started/hands-on/build-serverless-web-app-lambda-apigateway-s3-dynamodbcognito/module-4/
A21: 17 | B21: 一家公司每天从位于一家工厂的多台机器接收 10 TB 的仪器数据.这些数据由存储在工厂内部数据中心的存储区域网络(SAN)上的 JSON 文件组成.公司想要将此数据发送到 Amazon S3,在那里可以由几个提供关键近乎实时分析的附加系统访问它.安全传输很重要, 因为数据被认为是敏感的.哪种解决方案提供最可靠的数据传输? | C21: AWS DataSync 通过公共互联网 | D21: AWS DataSync 通过 AWS Direct Connect | E21: AWS Database Migration Service (AWS DMS) 通过公共互联网 | F21: AWS 数据库迁移服务(AWS DMS)通过 AWS Direct Connect | J21: B | K21: DMS 用于数据库,这里指的是“JSON文件”.公共互联网不可靠.所以最好的选择是 B.这些是 AWS DataSync 的一些主要用例 :数据迁移-通过网络将活动数据集快速移动到适用于 Windows File Server 的 Amazon S3.Amazon EFS 或 FSx.DataSync 包括自动加密和数据完整性验证以帮助确保您的数据安全.完整地到达并准备好使用.DataSync 包括加密和完整性验证,以帮助确保您的数据安全.完整地到达并准备好使用.https://aws.amazon.com/数据同步/常见问题/ | N21: DMS 用于数据库,这里指的是“JSON文件”.公共互联网不可靠.所以最好的选择是 B.这些是 AWS DataSync 的一些主要用例 :数据迁移-通过网络将活动数据集快速移动到适用于 Windows File Server 的 Amazon S3.Amazon EFS 或 FSx.DataSync 包括自动加密和数据完整性验证以帮助确保您的数据安全.完整地到达并准备好使用.DataSync 包括加密和完整性验证,以帮助确保您的数据安全.完整地到达并准备好使用.https://aws.amazon.com/数据同步/常见问题/
A22: 18 | B22: 一家公司需要为其应用程序配置实时数据摄取架构.该公司需要一个 API.一个在数据流式传输时转换数据的流程,以及一个数据存储解决方案.哪种解决方案将满足这些要求最少的运营开销? | C22: 部署 Amazon EC2 实例以托管将数据发送到 Amazon Kinesis 数据流的 API.创建使用 Kinesis 数据流作为数据源的 Amazon Kinesis Data Firehose 传输流.使用 AWS Lambda 函数转换数据.使用Kinesis Data Firehose 传输流将数据发送到 Amazon S3. | D22: 部署 Amazon EC2 实例以托管将数据发送到 AWS Glue 的 API.停止对 EC2 实例的源/目标检查.使用 AWS Glue 转换数据并将数据发送到 Amazon S3. | E22: 配置 Amazon API Gateway API 以将数据发送到 Amazon Kinesis 数据流.创建使用 Kinesis 数据流作为数据源的 Amazon Kinesis Data Firehose 传输流.使用 AWS Lambda 函数转换数据.使用 Kinesis Data Firehose 传输流将数据发送到 Amazon S3. | F22: 配置 Amazon API Gateway API 以将数据发送到 AWS Glue.使用 AWS Lambda 函数转换数据.使用 AWS Glue 将数据发送到 Amazon S3. | J22: C | K22: (A) - 您不需要部署 EC2 实例来托管 API - 操作开销. (B)- 与 A 相同. ( ** C*) - 就是答案. (D)- AWS Glue 从 S3 而非 API GW 获取数据. AWS Glue 可以自己做 ETL,所以不需要 lambda.无意义. https://aws.amazon.com/glue/. | N22: (A) - 您不需要部署 EC2 实例来托管 API - 操作开销. (B)- 与 A 相同. ( ** C*) - 就是答案. (D)- AWS Glue 从 S3 而非 API GW 获取数据. AWS Glue 可以自己做 ETL,所以不需要 lambda.无意义. https://aws.amazon.com/glue/.
A23: 19 | B23: 一家公司需要将用户交易数据保存在 Amazon DynamoDB 表中.该公司必须将数据保留 7年.满足这些要求的运营效率最高的解决方案是什么? | C23: 使用 DynamoDB 时间点恢复持续备份表. | D23: 使用 AWS Backup 为表创建备份计划和保留策略. | E23: 使用 DynamoDB 控制台创建表的按需备份.将备份存储在 Amazon S3 存储桶中.为 S3 存储桶设置 S3 生命周期配置. | F23: 创建 Amazon EventBridge (Amazon CloudWatch Events)规则以调用 AWS Lambda 函数.配置 Lambda 函数以备份表并将备份存储在 Amazon S3 存储桶中.为 S3 存储桶设置 S3 生命周期配置 | J23: B | K23: Amazon DynamoDB 提供两种类型的备份:时间点恢复(PITR)和按需备份. ( ==>D 不是答案) PITR 用于将您的表恢复到滚动的35天窗口中的任何时间点,用于帮助客户减少因错误代码.恶意访问或用户错误而对其表的意外删除或写入.( ==>A不是答案) 按需备份专为长期归档和保留而设计,通常用于帮助客户满足合规性和法规要求. 这是关于使用 AWS Backup 为 Amazon DynamoDB 设置计划按需备份的两篇博文系列中的第二篇.第1部分介绍了从AWS 管理控制台为 DynamoDB 表设置计划备份的步骤.( ==>不是 DynamoBD 控制台,C 也不是答案) https://aws.amazon.com/blogs/database/part-2-set-up-scheduled-backups-for-amazondynamodb-using-aws-backup/ | N23: Amazon DynamoDB 提供两种类型的备份:时间点恢复(PITR)和按需备份. ( ==>D 不是答案) PITR 用于将您的表恢复到滚动的35天窗口中的任何时间点,用于帮助客户减少因错误代码.恶意访问或用户错误而对其表的意外删除或写入.( ==>A不是答案) 按需备份专为长期归档和保留而设计,通常用于帮助客户满足合规性和法规要求. 这是关于使用 AWS Backup 为 Amazon DynamoDB 设置计划按需备份的两篇博文系列中的第二篇.第1部分介绍了从AWS 管理控制台为 DynamoDB 表设置计划备份的步骤.( ==>不是 DynamoBD 控制台,C 也不是答案) https://aws.amazon.com/blogs/database/part-2-set-up-scheduled-backups-for-amazondynamodb-using-aws-backup/
A24: 20 | B24: 某公司正计划使用 Amazon DynamoDB 表进行数据存储.该公司关注成本优化.大多数早上不会使用该表.在晚上,读写流量往往无法预测.当流量尖峰出现,它们会很快发生.解决方案架构师应该推荐什么? | C24: 在按需容量模式下创建DynamoDB表. | D24: 创建具有全局二级索引的 DynamoDB 表. | E24: 创建具有预置容量和 Auto Scaling 的 DynamoDB 表. | F24: 以预置容量模式创建DynamoDB表,并将其配置为全局表. | J24: A | K24: ** A ** - 按需提供答案 https://docs.aws.amazon.com/amazondynamodb/latest/developerguide/HowItWorks.ReadWriteCapacityMode.html#HowItWorks.OnDemand B - 与不可预测的流量无关. C- 推荐用于已知模式的预置容量.不是这里的情况. D- 与C 相同 | N24: ** A ** - 按需提供答案 https://docs.aws.amazon.com/amazondynamodb/latest/developerguide/HowItWorks.ReadWriteCapacityMode.html#HowItWorks.OnDemand B - 与不可预测的流量无关. C- 推荐用于已知模式的预置容量.不是这里的情况. D- 与C 相同
A25: 21 | B25: 一家公司最近与AWS托管服务提供商(MSP)合作伙伴签署了一份合同,以帮助实施应用程序迁移计划。解决方案架构师需要与 MSP合作伙伴的AWS帐户共享现有AWS帐户中的Amazon Machine Image (AMI)。AMI由Amazon Elastic Block Store (Amazon EBS)支持,并使用AWS密钥管理服务(AWS KMS)客户管理的密钥来加密EBS卷快照。解决方案架构师与MSP合作伙伴的AWS帐户共享AMI的最安全方式是什么? | C25: 公开加密的AMI和快照。修改密钥策略以允许MSP合作伙伴的AWS帐户使用密钥。 | D25: 修改AMI的launchPermission属性。仅与MSP合作伙伴的AWS帐户共享AMI。修改密钥策略以允许MSP合作伙伴的AWS帐户使用密钥。 | E25: 修改AMI的launchPermission属性。仅与MSP合作伙伴的AWS帐户共享AMI。修改密钥策略以信任MSP合作伙伴拥有的用于加密的新KMS密钥。 | F25: 将AMI从源帐户导出到MSP合作伙伴AWS帐户中的Amazon S3存储桶,使用MSP合作合作伙伴拥有的新KMS密钥加密S3存储桶。在MSP合作伙伴的AWS帐户中复制并启动AMI。 | J25: B
A26: 22 | B26: 一位解决方案架构师正在为部署在 AWS 上的新应用程序设计云架构.该过程应并行运行,同时根据要处理的作业数量根据需要添加和删除应用程序节点处理器应用程序是无状态的解决方案架构师必须确保应用程序是松散耦合的,并且工作项是持久存储的.解决方案架构师应该使用哪种设计? | C26: 创建 Amazon SNS 主题以发送需要处理的作业.创建包含处理器应用程序的 Amazon 系统映像(AMI).创建使用 AMI 的启动配置.使用启动配置创建 Auto Scaling 组.为 Auto Scaling 组设置伸缩策略,根据 CPU 使用率添加和删除节点. | D26: 创建 Amazon SQS 队列以保存需要处理的作业.创建包含处理器应用程序的 Amazon 机器映像(AMI).创建使用 AMI 的启动配置.使用启动配置创建 Auto Scaling 组.设置Auto Scaling组的伸缩策略,根据网络使用情况添加和删除节点, | E26: 创建 Amazon SQS 队列以保存需要处理的作业.创建包含处理器应用程序的 Amazon 机器映像(AMI).创建使用 AMI 的启动模板.使用启动模板创建 Auto Scaling 组.设置Auto Scaling 组的伸缩策略,根据SQS 队列中的项目数添加和删除节点. | F26: 创建 Amazon SNS 主题以发送需要处理的作业.创建包含处理器应用程序的 Amazon 系统映像(AMI).创建使用 AMI 的启动模板.使用启动模板创建 Auto Scaling 组.为Auto Scaling组设置伸缩策略,根据发布到SNS主题的消息数量添加和删除节点 | J26: C | K26: 创建一个 Amazon SQS 队列来保存需要处理的作业.为计算应用程序创建一个 Amazon EC2 Auto Scaling 组.为 Auto Scaling 组设置扩展策略以根据项目数量添加和删除节点在SQS 队列中.在这种情况下,我们需要找到一个持久且松散耦合的解决方案来存储作业.Amazon SQS 非常适合这种用例,并且可以配置为根据队列中等待的作业数量使用动态扩展.配置此缩放,您可以使用每个实例的积压指标,目标值是每个实例可接受的积压来维护,您可以按如下方式计算这些数字:每个实例的积压:要计算每个实例的积压,从 ApproximateNumberOfMessages 队列属性开始确定 SQS 队列的长度. | N26: 创建一个 Amazon SQS 队列来保存需要处理的作业.为计算应用程序创建一个 Amazon EC2 Auto Scaling 组.为 Auto Scaling 组设置扩展策略以根据项目数量添加和删除节点在SQS 队列中.在这种情况下,我们需要找到一个持久且松散耦合的解决方案来存储作业.Amazon SQS 非常适合这种用例,并且可以配置为根据队列中等待的作业数量使用动态扩展.配置此缩放,您可以使用每个实例的积压指标,目标值是每个实例可接受的积压来维护,您可以按如下方式计算这些数字:每个实例的积压:要计算每个实例的积压,从 ApproximateNumberOfMessages 队列属性开始确定 SQS 队列的长度.
A27: 23 | B27: 一家公司在 AWS 云中托管其 Web 应用程序.该公司将 Elastic Load Balancer 配置为使用导入 AWS Certificate Manager (ACM) 的证书.必须在每个证书到期前30天通知公司的安全团队.什么解决方案架构师应该推荐满足要求吗? | C27: 添加规则 ACM 以在任何证书到期前 30 天开始每天向 Amazon Simple Notification Service (Amazon SNS)主题发布自定义消息. | D27: 创建一个 AWS Config 规则来检查将在 30 天内过期的证书.配置 Amazon EventBridge (Amazon CloudWatch Events)以在 AWS Config 报告不合规资源时通过 Amazon Simple Notification Service (Amazon SNS)调用自定义警报 | E27: 使用 AWS Trusted Advisor 检查将在几天内过期的证书.创建基于 Trusted Advisor 指标的 Amazon CloudWatch 警报以检查状态更改.配置警报以通过 Amazon Simple rectification Service (亚马逊社交网络) | F27: 创建 Amazon EventBridge (Amazon CloudWatch Events)规则以检测任何将在30 天内过期的证书.配置规则以调用 AWS Lambda 函数.配置 Lambda 函数以通过 Amazon Simple Notification Service (亚马逊 SNS). | J27: B | K27: AWS Config 有一个名为 acm-certificate-expiration-check 的托管规则来检查过期证书(可配置的天#) .https://aws.amazon.com/premiumsupport/knowledge-center/acm-certificate-expiration/ | N27: AWS Config 有一个名为 acm-certificate-expiration-check 的托管规则来检查过期证书(可配置的天#) .https://aws.amazon.com/premiumsupport/knowledge-center/acm-certificate-expiration/
A28: 24 | B28: 一家公司的动态网站使用美国的本地服务器托管,该公司正在欧洲推出其产品,它希望优化新欧洲用户的网站加载时间.该网站的后端必须保留在美国.几天后产品上线,急需解决方案.解决方案架构师应该推荐什么? | C28: 在 us-east-1 中启动一个 Amazon EC2 实例并将站点迁移到该实例. | D28: 将网站移动到 Amazon S3.使用区域之间的跨区域复制. | E28: 将 Amazon CloudFront 与指向本地服务器的自定义源一起使用. | F28: 使用指向本地服务器的 Amazon Route 53 地理邻近路由策略. | J28: C | K28: https://aws.amazon.com/pt/blogs/aws/amazon-cloudfront-support-for-custom-origins/ 您现在可以使用自定义来源创建 CloudFront 分配.每个分配都可以指向一个S3或自定义来源,这可能是另一个存储服务,也可能是更有趣和更动态的东西,例如EC2 实例甚至弹性负载均衡器 | N28: https://aws.amazon.com/pt/blogs/aws/amazon-cloudfront-support-for-custom-origins/ 您现在可以使用自定义来源创建 CloudFront 分配.每个分配都可以指向一个S3或自定义来源,这可能是另一个存储服务,也可能是更有趣和更动态的东西,例如EC2 实例甚至弹性负载均衡器
A29: 25 | B29: 一家公司希望降低其现有三层Web 架构的成本.Web.应用程序和数据库服务器在 Amazon EC2 实例上运行,用于开发.测试和生产环境.EC2 实例平均 CPU 利用率为30%高峰时段和非高峰时段10%的 CPU 使用率.生产EC2 实例每天运行 24 小时.开发和测试 EC2 实例每天至少运行8小时.公司计划实施自动化以停止开发和在EC2 实例不使用时对其进行测试.哪种 EC2 实例购买解决方案最符合公司的要求? | C29: 将 Spot 实例用于生产 EC2 实例.将预留实例用于开发和测试 EC2 实例. | D29: 将预留实例用于生产EC2 实例.将按需实例用于开发和测试 EC2 实例. | E29: 将 Spot 块用于生产 EC2 实例.将预留实例用于开发和测试 EC2 实例. | F29: 将按需实例用于生产 EC2 实例.将 Spot 块用于开发和测试 EC2 实例. | J29: B | K29: Spot 块不再可用,并且您不能在 Prod 机器上 24x7 使用 Spot 实例,因此选项 B应该是有效的. | N29: Spot 块不再可用,并且您不能在 Prod 机器上 24x7 使用 Spot 实例,因此选项 B应该是有效的.
A30: 26 | B30: 一家公司有一个生产网络应用程序,用户通过网络接口或移动应用程序上传文档.根据新的法规要求,新文档存储后不能修改或删除.解决方案架构师应该做些什么来满足这个要求? | C30: 将上传的文档存储在启用S3 版本控制和 S3 对象锁定的 Amazon S3 存储桶中 | D30: 将上传的文档存储在 Amazon S3 存储桶中.配置 S3 生命周期策略以定期存档文档. | E30: 将上传的文档存储在启用了S3 版本控制的 Amazon S3 存储桶中.配置 ACL 以将所有访问权限限制为只读. | F30: 将上传的文档存储在 Amazon Elastic File System (Amazon EFS) 卷上,通过以只读模式挂载卷来访问数据. | J30: A | K30: 您可以使用 S3 对象锁来使用一次写入多次读取(WORM)模型存储对象.对象锁定可以帮助防止对象在固定时间或无限期被删除或覆盖.您可以使用 S3 对象锁定来满足需要 WORM 存储的法规要求,或者添加额外的保护层以防止对象更改和删除. 版本控制是必需的,并在后用对象锁定时自动激活. https://docs.aws.amazon.com/AmazonS3/latest/userguide/object-lock-overview.html | N30: 您可以使用 S3 对象锁来使用一次写入多次读取(WORM)模型存储对象.对象锁定可以帮助防止对象在固定时间或无限期被删除或覆盖.您可以使用 S3 对象锁定来满足需要 WORM 存储的法规要求,或者添加额外的保护层以防止对象更改和删除. 版本控制是必需的,并在后用对象锁定时自动激活. https://docs.aws.amazon.com/AmazonS3/latest/userguide/object-lock-overview.html
A31: 27 | B31: 一家公司有多个 Web 服务器,需要经常访问一个通用的 Amazon RDS MySQL 多可用区数据库实例.该公司想要一种安全的方法让Web 服务器连接到数据库,同时满足频繁轮换用户凭证的安全要求.哪种解决方案满足这些要求? | C31: 将数据库用户凭证存储在 AWS Secrets Manager 中.授予必要的 IAM 权限以允许 Web 服务器访问 AWS Secrets Manager. | D31: 将数据库用户凭证存储在 AWS Systems Manager OpsCenter 中.授予必要的 IAM 权限以允许 Web 服务器访问 OpsCenter. | E31: 将数据库用户凭证存储在安全的 Amazon S3 存储桶中.授予必要的 IAM 权限以允许 Web 服务器检索凭证并访问数据库. | F31: 将数据库用户凭证存储在 Web 服务器文件系统上使用 AWS Key Management Service (AWS KMS)加密的文件中.Web 服务器应该能够解密文件并访问数据库. | J31: A | K31: AWS Secrets Manager 可帮助您保护访问您的应用程序.服务和 IT 资源所需的机密,该服务使您能够在整个生命周期内轻松轮换.管理和检索数据库凭证.API 密钥和其他机密.https://docs.aws.amazon.com/secretsmanager/latest/userguide/intro.html | N31: AWS Secrets Manager 可帮助您保护访问您的应用程序.服务和 IT 资源所需的机密,该服务使您能够在整个生命周期内轻松轮换.管理和检索数据库凭证.API 密钥和其他机密.https://docs.aws.amazon.com/secretsmanager/latest/userguide/intro.html
A32: 28 | B32: 一家公司在 AWS 上托管应用程序 Lambda 函数由 Amazon API Gateway API 调用.Lambda 函数将客户数据保存到 Amazon Aurora MySQL 数据库中.每当公司升级数据库时,Lambda 函数都无法建立数据库连接,直到升级完成结果是某些事件没有记录客户数据.解决方案架构师需要设计一个解决方案来存储在数据库升级期间创建的客户数据.哪种解决方案可以满足这些要求? | C32: 在 Lambda 函数和数据库之间配置一个 Amazon RDS 代理.配置 Lambda 函数以连接到 RDS 代理, | D32: 将我的Lambda函数的运行时间最大化,在代码中创建重试机制,将客户数据存储在数据库中, | E32: 将客户数据持久化到 Lambda 本地存储.配置新的 Lambda 函数扫描本地存储,将客户数据保存到数据库. | F32: 将客户数据存储在 Amazon Simple Queue Service (Amazon SQS) FIFO 队列中.创建一个新的 Lambda 函数来轮询队列并将客户数据存储在数据库中. | J32: D | K32: The question is ' a solution that stores data' -- >So for me answer is D -- >Store data in SQS | N32: The question is ' a solution that stores data' -- >So for me answer is D -- >Store data in SQS
A33: 29 | B33: 一家调查公司从美国地区收集了数年的数据该公司将数据托管在一个大小为3 TB 且还在不断增长的 Amazon S3 存储桶中.该公司已开始与欧洲营销部内共享数据拥有S3 存储桶的公司,该公司希望确保其数据传输成本尽可能低.哪种解决方案可以满足这些要求? | C33: 在公司的 S3 存储桶上配置 Requester Pays 功能 | D33: 配置从公司的 S3 存储桶到营销公司的 S3 存储桶之一的S3 跨区域复制. | E33: 为营销公司配置跨账户访问,使营销公司可以访问公司的S3存储桶. | F33: 将公司的 S3 存储桶配置为使用 S3 Intelligent-Tiering 将 S3 存储桶同步到营销公司的S3 存储桶之一 | J33: A | K33: 通常,当您想要共享数据但不会产生与访问数据的其他人相关的费用时,您将存储桶配置为请求者支付存储桶.例如,您可以在提供大型数据集(例如邮政编码目录)时使用请求者支付存储桶.参考数据.地理空间信息或网络爬取数据. https://docs.aws.amazon.com/AmazonS3/latest/userguide/RequesterPaysBuckets.html | N33: 通常,当您想要共享数据但不会产生与访问数据的其他人相关的费用时,您将存储桶配置为请求者支付存储桶.例如,您可以在提供大型数据集(例如邮政编码目录)时使用请求者支付存储桶.参考数据.地理空间信息或网络爬取数据. https://docs.aws.amazon.com/AmazonS3/latest/userguide/RequesterPaysBuckets.html
A34: 30 | B34: 某公司使用 Amazon S3 存储其机密审计文档.S3 存储桶使用存储桶策略根据最小权限原则限制对审计团队 IAM用户凭证的访问.公司经理担心 S3 存储桶中的文档被意外删除并想要一个更安全的解决方案.解决方案架构师应该如何保护审计文件? | C34: 在 S3 存储桶上启用版本控制和 MFA 删除功能. | D34: 对每个审计团队 IAM 用户账户的IAM用户凭证后用多重身份验证(MFA). | E34: 向审计团队的 IAM 用户账户添加 S3 生命周期策略,以在审计日期拒绝 s3:DeleteObject 操作, | F34: 使用 AWS Key Management Service (AWS KMS)加密 S3 存储桶并限制审计团队 IAM 用户账户访问 KMS 密钥. | J34: A | K34: accidental deletion of documents in the S3 bucket and want a more secure solution | N34: accidental deletion of documents in the S3 bucket and want a more secure solution
A35: 31 | B35: 一家公司正在使用 SQL 数据库存储可公开访问的电影数据.该数据库在 Amazon RDS 单可用区数据库实例上运行.脚本每天以随机间隔运行查询,以记录已上映的新电影数量添加到数据库中.脚本必须在营业时间内报告最终总数.公司的开发团队注意到,当脚本运行时,数据库性能不足以完成开发任务.解决方案架构师必须推荐解决此问题的解决方案.哪个解决方案会以最少的运营开销满足这个要求吗? | C35: 将数据库实例修改为多可用区部署 | D35: 创建数据库的只读副本.将脚本配置为仅查询只读副本. | E35: 指示开发团队在每天结束时手动导出数据库中的条目 | F35: 使用 Amazon Elasticache 缓存脚本针对数据库运行的常见查询 | J35: B | K35: Elasti Cache 如果用于读取常见结果,该脚本正在寻找添加的新电影,只读副本将是最佳选择, | N35: Elasti Cache 如果用于读取常见结果,该脚本正在寻找添加的新电影,只读副本将是最佳选择,
A36: 32 | B36: 某公司有应用程序在VPC中的Amazon EC2实例上运行,其中一个应用程序需要调用Amazon S3 API来存储和读取对象.根据公司的安全规定,不允许来自应用程序的流量穿越互联网.哪种解决方案可以满足这些要求? | C36: 配置 S3 网关端点. | D36: 配置 S3 接口端点. | E36: 在私有子网中创建 S3 存储桶. | F36: 在与 EC2 实例相同的区域中创建一个 S3 存储桶. | J36: A | K36: 网关终端节点提供与 Amazon S3 和 DynamoDB 的可靠连接,而您的VPC 不需要互联网网关或 NAT 设备.它应该是选项A.https://docs.aws.amazon.com/AmazonS3/latest/userguide/privatelink-interface-endpoints.html#types-of-vpc-endpoints-for-s3 | N36: 网关终端节点提供与 Amazon S3 和 DynamoDB 的可靠连接,而您的VPC 不需要互联网网关或 NAT 设备.它应该是选项A.https://docs.aws.amazon.com/AmazonS3/latest/userguide/privatelink-interface-endpoints.html#types-of-vpc-endpoints-for-s3
A37: 33 | B37: 一家公司将敏感的用户信息存储在 Amazon S3 存储桶中,该公司希望从在 VPC 内的 Amazon EC2 实例上运行的应用程序层提供对该存储桶的安全访问.解决方案架构师应采取哪些步骤组合来完成此任务?(选择两个.) | C37: 为 VPC 内的 Amazon S3 配置 VPC 网关终端节点 | D37: 创建存储桶策略以将对象公开到 S3 存储桶 | E37: 创建存储桶策略,将访问限制为仅在 VPC 中运行的应用程序层 | F37: 使用 S3 访问策略创建 IAM 用户并将 IAM 凭证复制到 EC2 实例 | G37: 创建一个 NAT 实例并让 EC2 实例使用 NAT 实例访问 S3 存储桶 | J37: A,C | K37: https://aws.amazon.com/premiumsupport/knowledge-center/s3-private-connection-no-authentication/ | N37: https://aws.amazon.com/premiumsupport/knowledge-center/s3-private-connection-no-authentication/
A38: 34 | B38: 一家公司运行一个由 MySQL 数据库提供支持的本地应用程序,该公司正在将应用程序迁移到AWS 以提高应用程序的弹性和可用性.当前架构在正常操作期间显示数据库上的大量读取活动.公司的开发团队每 4 小时拉一次生产数据库的完整导出以填充暂存环境中的数据库.在此期间,用户会遇到不可接受的应用程序延迟.开发团队在程序完成之前无法使用暂存环境.A解决方案架构师必须推荐可缓解应用程序延迟问题的替代架构.替代架构还必须使开发团队能够继续使用暂存环境而不会延迟.哪种解决方案满足这些要求? | C38: 将 Amazon Aurora MySQL 与多可用区 Aurora 副本一起用于生产.通过实施使用 mysqldump 实用程序的备份和还原过程来填充暂存数据库. | D38: 使用 Amazon Aurora MySQL 和多可用区 Aurora 副本进行生产.使用数据库克隆按需创建临时数据库 | E38: 将 Amazon RDS for MySQL 与 Mufti AZ 部署和只读副本用于生产,将备用实例用于暂存数据库. | F38: 将 Amazon RDS for MySQL 与多可用区部署和只读副本用于生产,通过实施使用 mysqldump 实用程序的备份和还原过程来填充暂存数据库. | J38: B | K38: Amazon Aurora Fast Database Cloning is what is required here. https://aws.amazon.com/blogs/aws/amazon-aurora-fastdatabase-cloning/ | N38: Amazon Aurora Fast Database Cloning is what is required here. https://aws.amazon.com/blogs/aws/amazon-aurora-fastdatabase-cloning/
A39: 35 | B39: 一家公司正准备在 Amazon S3 中存储机密数据.出于合规性原因,必须对静态数据进行加密 必须记录加密密钥的使用以进行审计.必须每年轮换密钥.哪种解决方案满足这些要求并且在操作上最有效传出? | C39: 使用客户提供的密钥进行服务器端加密(SSE-C) | D39: 使用 Amazon S3 托管密钥的服务器端加密(SSE-S3) | E39: 使用 AWS KMS (SSE-KMS) 客户主密钥(CMK)手动轮换的服务器端加密 | F39: 使用 AWS KMS (SSE-KMS) 客户主密钥(CMK)进行服务器端加密并自动轮换 | J39: D | K39: https://docs.aws.amazon.com/kms/latest/developerguide/rotate-keys.html 当您为客户管理的密钥启用自动密钥轮换时,AWS KMS 每年都会为 KMS 密钥生成新的加密材料. AWS KMS 还永久保存 KMS 密钥的旧加密材料,因此可用于解密 KMS 密钥加密的数据.AWS KMS 中的密钥轮换是一种加密最佳实践,旨在透明且易于使用.AWS KMS 支持仅适用于客户管理的 CMK 的可选自动密钥轮换.启用和禁用密钥轮换.默认情况下,客户管理的 CMK 上禁用自动密钥轮换.启用(或重新启用)密钥轮换时,AWS KMS 自动轮换 CMK 365 天后启用日期和此后每 365 天. | N39: https://docs.aws.amazon.com/kms/latest/developerguide/rotate-keys.html 当您为客户管理的密钥启用自动密钥轮换时,AWS KMS 每年都会为 KMS 密钥生成新的加密材料. AWS KMS 还永久保存 KMS 密钥的旧加密材料,因此可用于解密 KMS 密钥加密的数据.AWS KMS 中的密钥轮换是一种加密最佳实践,旨在透明且易于使用.AWS KMS 支持仅适用于客户管理的 CMK 的可选自动密钥轮换.启用和禁用密钥轮换.默认情况下,客户管理的 CMK 上禁用自动密钥轮换.启用(或重新启用)密钥轮换时,AWS KMS 自动轮换 CMK 365 天后启用日期和此后每 365 天.
A40: 36 | B40: 一家自行车共享公司正在开发一种多层架构,以在高峰运营时间跟踪其自行车的位置,该公司希望在其现有的分析平台中使用这些数据点.解决方案架构师必须确定最可行的多层架构支持此架构的选项数据点必须可从 REST API 访问.哪个操作满足存储和检索位置数据的这些要求? | C40: 将 Amazon Athena 与 Amazon S3 结合使用 | D40: 将 Amazon API Gateway 与 AWS Lambda 结合使用 | E40: 将 Amazon QuickSight 与 Amazon Redshift 结合使用. | F40: 将 Amazon API Gateway 与 Amazon Kinesis Data Analytics 结合使用 | J40: B | K40: 需要 API 网关来获取数据,所以选项A和C不可用.“公司希望在其现有的分析平台中使用这些数据点”,因此无需添加 Kynesis.选项 D 也被淘汰了, 这给我们留下了选项 B 作为正确的选项. | N40: 需要 API 网关来获取数据,所以选项A和C不可用.“公司希望在其现有的分析平台中使用这些数据点”,因此无需添加 Kynesis.选项 D 也被淘汰了, 这给我们留下了选项 B 作为正确的选项.
A41: 37 | B41: 一家公司有一个汽车销售网站,该网站将其列表存储在 Amazon RDS 的数据库中,当汽车出售时,需要从网站上删除列表,并且必须将数据发送到多个目标系统.哪种设计应该是解决方案建筑师推荐? | C41: 创建在更新 Amazon RDS 上的数据库时触发的 AWS Lambda 函数,以将信息发送到 Amazon Simple Queue Service (Amazon SQS>队列以供目标使用 | D41: 创建在更新 Amazon RDS 上的数据库时触发的 AWS Lambda 函数,以将信息发送到 Amazon Simple Queue Service (Amazon | E41: 订阅 RDS 事件通知并将 Amazon Simple Queue Service (Amazon SQS) 队列发送到多个 Amazon Simple Notification Service (Amazon SNS) 主题使用 AWS Lambda 函数更新目标 | F41: 订阅 RDS 事件通知并将 Amazon Simple Notification Service (Amazon SNS) 主题扇出到多个 Amazon Simple Queue Service (Amazon SQS) 队列使用 AWS Lambda 函数更新目标 | J41: D | K41: https://docs.aws.amazon.com/lambda/latest/dg/services-rds.html https://docs.aws.amazon.com/lambda/latest/dg/withsns.html | N41: https://docs.aws.amazon.com/lambda/latest/dg/services-rds.html https://docs.aws.amazon.com/lambda/latest/dg/withsns.html
A42: 38 | B42: 公司需要将数据存储在 Amazon S3 中并且必须防止数据被更改.公司希望上传到 Amazon S3 的新对象在不特定的时间内保持不变,直到公司决定修改对象.仅公司 AWS账户中的特定用户可以拥有删除对象的能力.解决方案架构师应该怎么做才能满足这些要求? | C42: 创建 S3 Glacier 保险库 对对象应用一次写入.多次读取(WORM)保险库锁定策略. | D42: 创建启用 S3 对象锁定的 S3 存储桶启用版本控制.设置保留期为100年.使用治理模式作为新对象的S3 存储桶的默认保留模式. | E42: 创建 S3 存储桶.使用 AWS CloudTrail 跟踪修改对象的任何 S3 API 事件.收到通知后,从公司拥有的任何备份版本中恢复修改后的对象. | F42: 创建后用 S3 对象锁定的 S3 存储桶.启用版本控制.为对象添加合法保留.将 s3:PutObjectLegalHold 权限添加到需要删除对象的用户的 IAM 策略中. | J42: D | K42: A-否,因为“特定用户可以删除”. B- 不作为“非特定时间量”. C- 否,因为“防止数据被更改". D- 答案:“对象锁定合法保留操作使您能够对对象版本进行合法保留.与设置保留期一样,合法保留可防止对象版本被覆盖或删除.但是,合法保留不会“它有一个相关的保留期,并且在删除之前一直有效."https://docs.aws.amazon.com/AmazonS3/latest/userguide/batch-ops-legal-hold.html | N42: A-否,因为“特定用户可以删除”. B- 不作为“非特定时间量”. C- 否,因为“防止数据被更改". D- 答案:“对象锁定合法保留操作使您能够对对象版本进行合法保留.与设置保留期一样,合法保留可防止对象版本被覆盖或删除.但是,合法保留不会“它有一个相关的保留期,并且在删除之前一直有效."https://docs.aws.amazon.com/AmazonS3/latest/userguide/batch-ops-legal-hold.html
A43: 39 | B43: 一家社交媒体公司允许用户将图像上传到其网站.该网站在 Amazon EC2 实例上运行在上传请求期间,该网站将图像调整为标准尺寸并将调整后的图像存储在 Amazon S3 中.用户遇到上传缓慢的问题对网站的请求.公司需要减少应用程序内的耦合并提高网站性能.解决方案架构师必须设计最有效的图像上传流程.解决方案架构师应该采取哪些行动组合来满足这些要求?(选择两个.) | C43: 配置应用程序以将图像上传到 S3 Glacier. | D43: 配置 Web 服务器以将原始图像上传到 Amazon S3. | E43: 将应用程序配置为通过使用预签名 URL 将图像直接从每个用户的浏览器上传到 Amazon S3. | F43: 配置 S3 事件通知以在上传图像时调用 AWS Lambda 函数.使用该函数调整图像大小 | G43: 创建一个 Amazon EventBridge (Amazon CloudWatch Events)规则,该规则按计划调用 AWS Lambda 函数以调整上传图像的大小. | J43: B,D | K43: Event notifications - Trigger workflows that use Amazon Simple Notification Service (Amazon SNS), Amazon Simple Queue Service (Amazon SQS), and AWS Lambda when a change is made to your S3 resources.事件通知-当您的S3资源发生更改时,触发使用Amazon Simple Notification Service (Amazon SNS)、Amazon简单队列服务(AmazonSQS)和AWS Lambda的工作流。 https://docs.aws.amazon.com/AmazonS3/latest/userguide/Welcome.html | N43: Event notifications - Trigger workflows that use Amazon Simple Notification Service (Amazon SNS), Amazon Simple Queue Service (Amazon SQS), and AWS Lambda when a change is made to your S3 resources.事件通知-当您的S3资源发生更改时,触发使用Amazon Simple Notification Service (Amazon SNS)、Amazon简单队列服务(AmazonSQS)和AWS Lambda的工作流。 https://docs.aws.amazon.com/AmazonS3/latest/userguide/Welcome.html
...

Sheet 1-100
A1: 📘 AWS-SAA-C03 顺序刷题（1-100）
A2: 在每题「你的答案」输入 A 或 C,D（英文逗号）后，才会显示：结果 / 正确答案 / 解析，并自动对选项标色（绿=正确，红=你选错）。
A3: {=_xlfn.LET(_xlpm.ans,SUMPRODUCT(($A$4:$A$1304="你的答案")*($B$4:$B$1304<>"")),_xlpm.corr,SUMPRODUCT(($A$4:$A$1304="结果")*($B$4:$B$1304="✅正确")),_xlpm.total,COUNTIF($A$4:$A$1304,"题目 *"),_xlpm.rate,IF(_xlpm.ans=0,0,_xlpm.corr/_xlpm.ans),"📊 进度：已作答 "&_xlpm.ans&"/"&_xlpm.total&" | 正确 "&_xlpm.corr&" | 正确率 "&TEXT(_xlpm.rate,"0.0%"))} -> 📊 进度：已作答 0/100 | 正确 0 | 正确率 0.0%
A4: 题目 1： | B4: 一家公司有一个托管在 AWS 上的网站该网站位于应用程序负载均衡器(ALB)的后面,该应用程序负载均衡器(ALB)配置为分别处理 HTTP 和 HTTPS.该公司希望将所有请求转发到该网站,以便这些请求将使用 HTTPS.什么解决方案架构师应该做些什么来满足这个要求? | D4: {=_xlfn.LET(_xlpm.v,INDEX($B:$B, 4 + INT((ROW()-4)/13)*13 + 8), IF(_xlpm.v=0,"",_xlpm.v))} | F4: =1 -> 1 | G4: =_xlfn.XLOOKUP($F4,题库数据!$A$5:$A$104,题库数据!$J$5:$J$104,"") -> C | H4: =_xlfn.LET(_xlpm.v,_xlfn.XLOOKUP(F4,题库数据!$A$5:$A$104,题库数据!$K$5:$K$104,""),IF(OR(_xlpm.v="",_xlpm.v=0),"",_xlpm.v)) -> Cant be implemented on Lambda because the timeout for Lambda is 15mins and the Job takes 60minutes to complete
D5: {=_xlfn.LET(_xlpm.v,INDEX($B:$B, 4 + INT((ROW()-4)/13)*13 + 8), IF(_xlpm.v=0,"",_xlpm.v))} | F5: =1 -> 1 | G5: =_xlfn.XLOOKUP($F5,题库数据!$A$5:$A$104,题库数据!$J$5:$J$104,"") -> C | H5: =_xlfn.LET(_xlpm.v,_xlfn.XLOOKUP(F5,题库数据!$A$5:$A$104,题库数据!$K$5:$K$104,""),IF(OR(_xlpm.v="",_xlpm.v=0),"",_xlpm.v)) -> Cant be implemented on Lambda because the timeout for Lambda is 15mins and the Job takes 60minutes to complete
A6: A: | B6: =_xlfn.XLOOKUP($F6,题库[题号],题库[选项A]) -> 更新 ALB 的网络 ACL 以仅接受 HTTPS 流量 | D6: {=_xlfn.LET(_xlpm.v,INDEX($B:$B, 4 + INT((ROW()-4)/13)*13 + 8), IF(_xlpm.v=0,"",_xlpm.v))} | F6: =1 -> 1 | G6: =_xlfn.XLOOKUP($F6,题库数据!$A$5:$A$104,题库数据!$J$5:$J$104,"") -> C | H6: =_xlfn.LET(_xlpm.v,_xlfn.XLOOKUP(F6,题库数据!$A$5:$A$104,题库数据!$K$5:$K$104,""),IF(OR(_xlpm.v="",_xlpm.v=0),"",_xlpm.v)) -> Cant be implemented on Lambda because the timeout for Lambda is 15mins and the Job takes 60minutes to complete
A7: B: | B7: =_xlfn.XLOOKUP($F7,题库[题号],题库[选项B]) -> 创建一个规则,将 URL 中的 HTTP 替换为 HTTPS. | D7: {=_xlfn.LET(_xlpm.v,INDEX($B:$B, 4 + INT((ROW()-4)/13)*13 + 8), IF(_xlpm.v=0,"",_xlpm.v))} | F7: =1 -> 1 | G7: =_xlfn.XLOOKUP($F7,题库数据!$A$5:$A$104,题库数据!$J$5:$J$104,"") -> C | H7: =_xlfn.LET(_xlpm.v,_xlfn.XLOOKUP(F7,题库数据!$A$5:$A$104,题库数据!$K$5:$K$104,""),IF(OR(_xlpm.v="",_xlpm.v=0),"",_xlpm.v)) -> Cant be implemented on Lambda because the timeout for Lambda is 15mins and the Job takes 60minutes to complete
A8: C: | B8: =_xlfn.XLOOKUP($F8,题库[题号],题库[选项C]) -> 在 ALB 上创建一个监听器规则,将 HTTP 流量重定向到 HTTPS. | D8: {=_xlfn.LET(_xlpm.v,INDEX($B:$B, 4 + INT((ROW()-4)/13)*13 + 8), IF(_xlpm.v=0,"",_xlpm.v))} | F8: =1 -> 1 | G8: =_xlfn.XLOOKUP($F8,题库数据!$A$5:$A$104,题库数据!$J$5:$J$104,"") -> C | H8: =_xlfn.LET(_xlpm.v,_xlfn.XLOOKUP(F8,题库数据!$A$5:$A$104,题库数据!$K$5:$K$104,""),IF(OR(_xlpm.v="",_xlpm.v=0),"",_xlpm.v)) -> Cant be implemented on Lambda because the timeout for Lambda is 15mins and the Job takes 60minutes to complete
A9: D: | B9: =_xlfn.XLOOKUP($F9,题库[题号],题库[选项D]) -> 将 ALB 替换为配置为使用服务器名称指示(SNI)的网络负载均衡器. | D9: {=_xlfn.LET(_xlpm.v,INDEX($B:$B, 4 + INT((ROW()-4)/13)*13 + 8), IF(_xlpm.v=0,"",_xlpm.v))} | F9: =1 -> 1 | G9: =_xlfn.XLOOKUP($F9,题库数据!$A$5:$A$104,题库数据!$J$5:$J$104,"") -> C | H9: =_xlfn.LET(_xlpm.v,_xlfn.XLOOKUP(F9,题库数据!$A$5:$A$104,题库数据!$K$5:$K$104,""),IF(OR(_xlpm.v="",_xlpm.v=0),"",_xlpm.v)) -> Cant be implemented on Lambda because the timeout for Lambda is 15mins and the Job takes 60minutes to complete
B10: =_xlfn.LET(_xlpm.v,_xlfn.XLOOKUP($F10,题库[题号],题库[选项E],""),IF(OR(_xlpm.v="",_xlpm.v=0),"",_xlpm.v)) | D10: {=_xlfn.LET(_xlpm.v,INDEX($B:$B, 4 + INT((ROW()-4)/13)*13 + 8), IF(_xlpm.v=0,"",_xlpm.v))} | F10: =1 -> 1 | G10: =_xlfn.XLOOKUP($F10,题库数据!$A$5:$A$104,题库数据!$J$5:$J$104,"") -> C | H10: =_xlfn.LET(_xlpm.v,_xlfn.XLOOKUP(F10,题库数据!$A$5:$A$104,题库数据!$K$5:$K$104,""),IF(OR(_xlpm.v="",_xlpm.v=0),"",_xlpm.v)) -> Cant be implemented on Lambda because the timeout for Lambda is 15mins and the Job takes 60minutes to complete
B11: =_xlfn.LET(_xlpm.v,_xlfn.XLOOKUP($F11,题库[题号],题库[选项F],""),IF(OR(_xlpm.v="",_xlpm.v=0),"",_xlpm.v)) | D11: {=_xlfn.LET(_xlpm.v,INDEX($B:$B, 4 + INT((ROW()-4)/13)*13 + 8), IF(_xlpm.v=0,"",_xlpm.v))} | F11: =1 -> 1 | G11: =_xlfn.XLOOKUP($F11,题库数据!$A$5:$A$104,题库数据!$J$5:$J$104,"") -> C | H11: =_xlfn.LET(_xlpm.v,_xlfn.XLOOKUP(F11,题库数据!$A$5:$A$104,题库数据!$K$5:$K$104,""),IF(OR(_xlpm.v="",_xlpm.v=0),"",_xlpm.v)) -> Cant be implemented on Lambda because the timeout for Lambda is 15mins and the Job takes 60minutes to complete
A12: 你的答案 | D12: {=_xlfn.LET(_xlpm.v,INDEX($B:$B, 4 + INT((ROW()-4)/13)*13 + 8), IF(_xlpm.v=0,"",_xlpm.v))} | F12: =1 -> 1 | G12: =_xlfn.XLOOKUP($F12,题库数据!$A$5:$A$104,题库数据!$J$5:$J$104,"") -> C | H12: =_xlfn.LET(_xlpm.v,_xlfn.XLOOKUP(F12,题库数据!$A$5:$A$104,题库数据!$K$5:$K$104,""),IF(OR(_xlpm.v="",_xlpm.v=0),"",_xlpm.v)) -> Cant be implemented on Lambda because the timeout for Lambda is 15mins and the Job takes 60minutes to complete
A13: 结果 | B13: =_xlfn.LET(_xlpm.inp,$B$12,_xlpm.nInp,_xlfn.LET(_xlpm.raw,UPPER(TRIM($B$12)),_xlpm.clean,SUBSTITUTE(SUBSTITUTE(SUBSTITUTE(SUBSTITUTE(SUBSTITUTE(_xlpm.raw,"，",","),"、",","),"；",",")," ",""),",",""),_xlfn.TEXTJOIN(",",TRUE,IF(ISNUMBER(SEARCH("A",_xlpm.clean)),"A",""),IF(ISNUMBER(SEARCH("B",_xlpm.clean)),"B",""),IF(ISNUMBER(SEARCH("C",_xlpm.clean)),"C",""),IF(ISNUMBER(SEARCH("D",_xlpm.clean)),"D",""),IF(ISNUMBER(SEARCH("E",_xlpm.clean)),"E",""),IF(ISNUMBER(SEARCH("F",_xlpm.clean)),"F",""))),_xlpm.nStd,_xlfn.LET(_xlpm.raw,UPPER(TRIM($G$4)),_xlpm.clean,SUBSTITUTE(SUBSTITUTE(SUBSTITUTE(SUBSTITUTE(SUBSTITUTE(_xlpm.raw,"，",","),"、",","),"；",",")," ",""),",",""),_xlfn.TEXTJOIN(",",TRUE,IF(ISNUMBER(SEARCH("A",_xlpm.clean)),"A",""),IF(ISNUMBER(SEARCH("B",_xlpm.clean)),"B",""),IF(ISNUMBER(SEARCH("C",_xlpm.clean)),"C",""),IF(ISNUMBER(SEARCH("D",_xlpm.clean)),"D",""),IF(ISNUMBER(SEARCH("E",_xlpm.clean)),"E",""),IF(ISNUMBER(SEARCH("F",_xlpm.clean)),"F",""))),IF(LEN(TRIM(_xlpm.inp))=0,"",IF(AND(_xlpm.nInp<>"",_xlpm.nStd<>"",_xlpm.nInp=_xlpm.nStd),"✅正确","❌错误"))) | D13: {=_xlfn.LET(_xlpm.v,INDEX($B:$B, 4 + INT((ROW()-4)/13)*13 + 8), IF(_xlpm.v=0,"",_xlpm.v))} | F13: =1 -> 1 | G13: =_xlfn.XLOOKUP($F13,题库数据!$A$5:$A$104,题库数据!$J$5:$J$104,"") -> C | H13: =_xlfn.LET(_xlpm.v,_xlfn.XLOOKUP(F13,题库数据!$A$5:$A$104,题库数据!$K$5:$K$104,""),IF(OR(_xlpm.v="",_xlpm.v=0),"",_xlpm.v)) -> Cant be implemented on Lambda because the timeout for Lambda is 15mins and the Job takes 60minutes to complete
A14: 正确答案 | B14: =_xlfn.LET(_xlpm.inp,$B$12,_xlpm.nStd,_xlfn.LET(_xlpm.raw,UPPER(TRIM($G$4)),_xlpm.clean,SUBSTITUTE(SUBSTITUTE(SUBSTITUTE(SUBSTITUTE(SUBSTITUTE(_xlpm.raw,"，",","),"、",","),"；",",")," ",""),",",""),_xlfn.TEXTJOIN(",",TRUE,IF(ISNUMBER(SEARCH("A",_xlpm.clean)),"A",""),IF(ISNUMBER(SEARCH("B",_xlpm.clean)),"B",""),IF(ISNUMBER(SEARCH("C",_xlpm.clean)),"C",""),IF(ISNUMBER(SEARCH("D",_xlpm.clean)),"D",""),IF(ISNUMBER(SEARCH("E",_xlpm.clean)),"E",""),IF(ISNUMBER(SEARCH("F",_xlpm.clean)),"F",""))),IF(OR(LEN(TRIM(_xlpm.inp))=0,_xlpm.nStd=""),"",_xlpm.nStd)) | D14: {=_xlfn.LET(_xlpm.v,INDEX($B:$B, 4 + INT((ROW()-4)/13)*13 + 8), IF(_xlpm.v=0,"",_xlpm.v))} | F14: =1 -> 1 | G14: =_xlfn.XLOOKUP($F14,题库数据!$A$5:$A$104,题库数据!$J$5:$J$104,"") -> C | H14: =_xlfn.LET(_xlpm.v,_xlfn.XLOOKUP(F14,题库数据!$A$5:$A$104,题库数据!$K$5:$K$104,""),IF(OR(_xlpm.v="",_xlpm.v=0),"",_xlpm.v)) -> Cant be implemented on Lambda because the timeout for Lambda is 15mins and the Job takes 60minutes to complete
A15: 解析 | B15: =_xlfn.LET(_xlpm.inp,$B$12,_xlpm.p,$H$4,IF(OR(LEN(TRIM(_xlpm.inp))=0,LEN(TRIM(_xlpm.p))=0,_xlpm.p=0),"",_xlpm.p)) | D15: {=_xlfn.LET(_xlpm.v,INDEX($B:$B, 4 + INT((ROW()-4)/13)*13 + 8), IF(_xlpm.v=0,"",_xlpm.v))} | F15: =1 -> 1 | G15: =_xlfn.XLOOKUP($F15,题库数据!$A$5:$A$104,题库数据!$J$5:$J$104,"") -> C | H15: =_xlfn.LET(_xlpm.v,_xlfn.XLOOKUP(F15,题库数据!$A$5:$A$104,题库数据!$K$5:$K$104,""),IF(OR(_xlpm.v="",_xlpm.v=0),"",_xlpm.v)) -> Cant be implemented on Lambda because the timeout for Lambda is 15mins and the Job takes 60minutes to complete
D16: {=_xlfn.LET(_xlpm.v,INDEX($B:$B, 4 + INT((ROW()-4)/13)*13 + 8), IF(_xlpm.v=0,"",_xlpm.v))} | F16: =1 -> 1 | G16: =_xlfn.XLOOKUP($F16,题库数据!$A$5:$A$104,题库数据!$J$5:$J$104,"") -> C | H16: =_xlfn.LET(_xlpm.v,_xlfn.XLOOKUP(F16,题库数据!$A$5:$A$104,题库数据!$K$5:$K$104,""),IF(OR(_xlpm.v="",_xlpm.v=0),"",_xlpm.v)) -> Cant be implemented on Lambda because the timeout for Lambda is 15mins and the Job takes 60minutes to complete
A17: 题目 2： | B17: 一家公司正在 AWS 上开发一个两层 Web 应用程序,该公司的开发人员已将该应用程序部署在直接连接到后端 Amazon RDS 数据库的 Amazon EC2 实例上.该公司不得在应用程序中硬编码数据库凭证.该公司还必须实施定期自动轮换数据库凭据的解决方案.哪种解决方案能够以最少的运营开销满足这些要求? | D17: {=_xlfn.LET(_xlpm.v,INDEX($B:$B, 4 + INT((ROW()-4)/13)*13 + 8), IF(_xlpm.v=0,"",_xlpm.v))} | F17: =2 -> 2 | G17: =_xlfn.XLOOKUP($F17,题库数据!$A$5:$A$104,题库数据!$J$5:$J$104,"") -> C | H17: =_xlfn.LET(_xlpm.v,_xlfn.XLOOKUP(F17,题库数据!$A$5:$A$104,题库数据!$K$5:$K$104,""),IF(OR(_xlpm.v="",_xlpm.v=0),"",_xlpm.v)) -> AWS Secrets Manager 是比 SSM Parameter store 更新的服务. https://docs.aws.amazon.com/secretsmanager/latest/userguide/create_database_secret.html
D18: {=_xlfn.LET(_xlpm.v,INDEX($B:$B, 4 + INT((ROW()-4)/13)*13 + 8), IF(_xlpm.v=0,"",_xlpm.v))} | F18: =2 -> 2 | G18: =_xlfn.XLOOKUP($F18,题库数据!$A$5:$A$104,题库数据!$J$5:$J$104,"") -> C | H18: =_xlfn.LET(_xlpm.v,_xlfn.XLOOKUP(F18,题库数据!$A$5:$A$104,题库数据!$K$5:$K$104,""),IF(OR(_xlpm.v="",_xlpm.v=0),"",_xlpm.v)) -> AWS Secrets Manager 是比 SSM Parameter store 更新的服务. https://docs.aws.amazon.com/secretsmanager/latest/userguide/create_database_secret.html
A19: A: | B19: =_xlfn.XLOOKUP($F19,题库[题号],题库[选项A]) -> 将数据库凭证存储在实例元数据中.使用 Amazon EventBridge (Amazon CloudWatch Events)规则运行计划的 AWS Lambda 函数,该函数同时更新 RDS 凭证和实例元数据. | D19: {=_xlfn.LET(_xlpm.v,INDEX($B:$B, 4 + INT((ROW()-4)/13)*13 + 8), IF(_xlpm.v=0,"",_xlpm.v))} | F19: =2 -> 2 | G19: =_xlfn.XLOOKUP($F19,题库数据!$A$5:$A$104,题库数据!$J$5:$J$104,"") -> C | H19: =_xlfn.LET(_xlpm.v,_xlfn.XLOOKUP(F19,题库数据!$A$5:$A$104,题库数据!$K$5:$K$104,""),IF(OR(_xlpm.v="",_xlpm.v=0),"",_xlpm.v)) -> AWS Secrets Manager 是比 SSM Parameter store 更新的服务. https://docs.aws.amazon.com/secretsmanager/latest/userguide/create_database_secret.html
A20: B: | B20: =_xlfn.XLOOKUP($F20,题库[题号],题库[选项B]) -> 将数据库凭证存储在加密 Amazon S3 存储桶中的配置文件中.使用 Amazon EventBridge (Amazon CloudWatch Events)规则运行计划的 AWS Lambda 函数,该函数同时更新 RDS 凭证和配置文件中的凭证.使用 S3 版本控制确保能够回退到以前的值. | D20: {=_xlfn.LET(_xlpm.v,INDEX($B:$B, 4 + INT((ROW()-4)/13)*13 + 8), IF(_xlpm.v=0,"",_xlpm.v))} | F20: =2 -> 2 | G20: =_xlfn.XLOOKUP($F20,题库数据!$A$5:$A$104,题库数据!$J$5:$J$104,"") -> C | H20: =_xlfn.LET(_xlpm.v,_xlfn.XLOOKUP(F20,题库数据!$A$5:$A$104,题库数据!$K$5:$K$104,""),IF(OR(_xlpm.v="",_xlpm.v=0),"",_xlpm.v)) -> AWS Secrets Manager 是比 SSM Parameter store 更新的服务. https://docs.aws.amazon.com/secretsmanager/latest/userguide/create_database_secret.html
A21: C: | B21: =_xlfn.XLOOKUP($F21,题库[题号],题库[选项C]) -> 将数据库凭证作为秘密存储在 AWS Secrets Manager 中.打开秘密的自动轮换.将所需的权限附加到EC2 角色以授予对秘密的访问权限. | D21: {=_xlfn.LET(_xlpm.v,INDEX($B:$B, 4 + INT((ROW()-4)/13)*13 + 8), IF(_xlpm.v=0,"",_xlpm.v))} | F21: =2 -> 2 | G21: =_xlfn.XLOOKUP($F21,题库数据!$A$5:$A$104,题库数据!$J$5:$J$104,"") -> C | H21: =_xlfn.LET(_xlpm.v,_xlfn.XLOOKUP(F21,题库数据!$A$5:$A$104,题库数据!$K$5:$K$104,""),IF(OR(_xlpm.v="",_xlpm.v=0),"",_xlpm.v)) -> AWS Secrets Manager 是比 SSM Parameter store 更新的服务. https://docs.aws.amazon.com/secretsmanager/latest/userguide/create_database_secret.html
A22: D: | B22: =_xlfn.XLOOKUP($F22,题库[题号],题库[选项D]) -> 将数据库凭证作为加密参数存储在 AWS Systems Manager Parameter Store 中.为加密参数启用自动轮换.将所需权限附加到 EC2 角色以授予对加密参数的访问权限. | D22: {=_xlfn.LET(_xlpm.v,INDEX($B:$B, 4 + INT((ROW()-4)/13)*13 + 8), IF(_xlpm.v=0,"",_xlpm.v))} | F22: =2 -> 2 | G22: =_xlfn.XLOOKUP($F22,题库数据!$A$5:$A$104,题库数据!$J$5:$J$104,"") -> C | H22: =_xlfn.LET(_xlpm.v,_xlfn.XLOOKUP(F22,题库数据!$A$5:$A$104,题库数据!$K$5:$K$104,""),IF(OR(_xlpm.v="",_xlpm.v=0),"",_xlpm.v)) -> AWS Secrets Manager 是比 SSM Parameter store 更新的服务. https://docs.aws.amazon.com/secretsmanager/latest/userguide/create_database_secret.html
B23: =_xlfn.LET(_xlpm.v,_xlfn.XLOOKUP($F23,题库[题号],题库[选项E],""),IF(OR(_xlpm.v="",_xlpm.v=0),"",_xlpm.v)) | D23: {=_xlfn.LET(_xlpm.v,INDEX($B:$B, 4 + INT((ROW()-4)/13)*13 + 8), IF(_xlpm.v=0,"",_xlpm.v))} | F23: =2 -> 2 | G23: =_xlfn.XLOOKUP($F23,题库数据!$A$5:$A$104,题库数据!$J$5:$J$104,"") -> C | H23: =_xlfn.LET(_xlpm.v,_xlfn.XLOOKUP(F23,题库数据!$A$5:$A$104,题库数据!$K$5:$K$104,""),IF(OR(_xlpm.v="",_xlpm.v=0),"",_xlpm.v)) -> AWS Secrets Manager 是比 SSM Parameter store 更新的服务. https://docs.aws.amazon.com/secretsmanager/latest/userguide/create_database_secret.html
B24: =_xlfn.LET(_xlpm.v,_xlfn.XLOOKUP($F24,题库[题号],题库[选项F],""),IF(OR(_xlpm.v="",_xlpm.v=0),"",_xlpm.v)) | D24: {=_xlfn.LET(_xlpm.v,INDEX($B:$B, 4 + INT((ROW()-4)/13)*13 + 8), IF(_xlpm.v=0,"",_xlpm.v))} | F24: =2 -> 2 | G24: =_xlfn.XLOOKUP($F24,题库数据!$A$5:$A$104,题库数据!$J$5:$J$104,"") -> C | H24: =_xlfn.LET(_xlpm.v,_xlfn.XLOOKUP(F24,题库数据!$A$5:$A$104,题库数据!$K$5:$K$104,""),IF(OR(_xlpm.v="",_xlpm.v=0),"",_xlpm.v)) -> AWS Secrets Manager 是比 SSM Parameter store 更新的服务. https://docs.aws.amazon.com/secretsmanager/latest/userguide/create_database_secret.html
A25: 你的答案 | D25: {=_xlfn.LET(_xlpm.v,INDEX($B:$B, 4 + INT((ROW()-4)/13)*13 + 8), IF(_xlpm.v=0,"",_xlpm.v))} | F25: =2 -> 2 | G25: =_xlfn.XLOOKUP($F25,题库数据!$A$5:$A$104,题库数据!$J$5:$J$104,"") -> C | H25: =_xlfn.LET(_xlpm.v,_xlfn.XLOOKUP(F25,题库数据!$A$5:$A$104,题库数据!$K$5:$K$104,""),IF(OR(_xlpm.v="",_xlpm.v=0),"",_xlpm.v)) -> AWS Secrets Manager 是比 SSM Parameter store 更新的服务. https://docs.aws.amazon.com/secretsmanager/latest/userguide/create_database_secret.html
A26: 结果 | B26: =_xlfn.LET(_xlpm.inp,$B$25,_xlpm.nInp,_xlfn.LET(_xlpm.raw,UPPER(TRIM($B$25)),_xlpm.clean,SUBSTITUTE(SUBSTITUTE(SUBSTITUTE(SUBSTITUTE(SUBSTITUTE(_xlpm.raw,"，",","),"、",","),"；",",")," ",""),",",""),_xlfn.TEXTJOIN(",",TRUE,IF(ISNUMBER(SEARCH("A",_xlpm.clean)),"A",""),IF(ISNUMBER(SEARCH("B",_xlpm.clean)),"B",""),IF(ISNUMBER(SEARCH("C",_xlpm.clean)),"C",""),IF(ISNUMBER(SEARCH("D",_xlpm.clean)),"D",""),IF(ISNUMBER(SEARCH("E",_xlpm.clean)),"E",""),IF(ISNUMBER(SEARCH("F",_xlpm.clean)),"F",""))),_xlpm.nStd,_xlfn.LET(_xlpm.raw,UPPER(TRIM($G$17)),_xlpm.clean,SUBSTITUTE(SUBSTITUTE(SUBSTITUTE(SUBSTITUTE(SUBSTITUTE(_xlpm.raw,"，",","),"、",","),"；",",")," ",""),",",""),_xlfn.TEXTJOIN(",",TRUE,IF(ISNUMBER(SEARCH("A",_xlpm.clean)),"A",""),IF(ISNUMBER(SEARCH("B",_xlpm.clean)),"B",""),IF(ISNUMBER(SEARCH("C",_xlpm.clean)),"C",""),IF(ISNUMBER(SEARCH("D",_xlpm.clean)),"D",""),IF(ISNUMBER(SEARCH("E",_xlpm.clean)),"E",""),IF(ISNUMBER(SEARCH("F",_xlpm.clean)),"F",""))),IF(LEN(TRIM(_xlpm.inp))=0,"",IF(AND(_xlpm.nInp<>"",_xlpm.nStd<>"",_xlpm.nInp=_xlpm.nStd),"✅正确","❌错误"))) | D26: {=_xlfn.LET(_xlpm.v,INDEX($B:$B, 4 + INT((ROW()-4)/13)*13 + 8), IF(_xlpm.v=0,"",_xlpm.v))} | F26: =2 -> 2 | G26: =_xlfn.XLOOKUP($F26,题库数据!$A$5:$A$104,题库数据!$J$5:$J$104,"") -> C | H26: =_xlfn.LET(_xlpm.v,_xlfn.XLOOKUP(F26,题库数据!$A$5:$A$104,题库数据!$K$5:$K$104,""),IF(OR(_xlpm.v="",_xlpm.v=0),"",_xlpm.v)) -> AWS Secrets Manager 是比 SSM Parameter store 更新的服务. https://docs.aws.amazon.com/secretsmanager/latest/userguide/create_database_secret.html
A27: 正确答案 | B27: =_xlfn.LET(_xlpm.inp,$B$25,_xlpm.nStd,_xlfn.LET(_xlpm.raw,UPPER(TRIM($G$17)),_xlpm.clean,SUBSTITUTE(SUBSTITUTE(SUBSTITUTE(SUBSTITUTE(SUBSTITUTE(_xlpm.raw,"，",","),"、",","),"；",",")," ",""),",",""),_xlfn.TEXTJOIN(",",TRUE,IF(ISNUMBER(SEARCH("A",_xlpm.clean)),"A",""),IF(ISNUMBER(SEARCH("B",_xlpm.clean)),"B",""),IF(ISNUMBER(SEARCH("C",_xlpm.clean)),"C",""),IF(ISNUMBER(SEARCH("D",_xlpm.clean)),"D",""),IF(ISNUMBER(SEARCH("E",_xlpm.clean)),"E",""),IF(ISNUMBER(SEARCH("F",_xlpm.clean)),"F",""))),IF(OR(LEN(TRIM(_xlpm.inp))=0,_xlpm.nStd=""),"",_xlpm.nStd)) | D27: {=_xlfn.LET(_xlpm.v,INDEX($B:$B, 4 + INT((ROW()-4)/13)*13 + 8), IF(_xlpm.v=0,"",_xlpm.v))} | F27: =2 -> 2 | G27: =_xlfn.XLOOKUP($F27,题库数据!$A$5:$A$104,题库数据!$J$5:$J$104,"") -> C | H27: =_xlfn.LET(_xlpm.v,_xlfn.XLOOKUP(F27,题库数据!$A$5:$A$104,题库数据!$K$5:$K$104,""),IF(OR(_xlpm.v="",_xlpm.v=0),"",_xlpm.v)) -> AWS Secrets Manager 是比 SSM Parameter store 更新的服务. https://docs.aws.amazon.com/secretsmanager/latest/userguide/create_database_secret.html
A28: 解析 | B28: =_xlfn.LET(_xlpm.inp,$B$25,_xlpm.p,$H$17,IF(OR(LEN(TRIM(_xlpm.inp))=0,LEN(TRIM(_xlpm.p))=0,_xlpm.p=0),"",_xlpm.p)) | D28: {=_xlfn.LET(_xlpm.v,INDEX($B:$B, 4 + INT((ROW()-4)/13)*13 + 8), IF(_xlpm.v=0,"",_xlpm.v))} | F28: =2 -> 2 | G28: =_xlfn.XLOOKUP($F28,题库数据!$A$5:$A$104,题库数据!$J$5:$J$104,"") -> C | H28: =_xlfn.LET(_xlpm.v,_xlfn.XLOOKUP(F28,题库数据!$A$5:$A$104,题库数据!$K$5:$K$104,""),IF(OR(_xlpm.v="",_xlpm.v=0),"",_xlpm.v)) -> AWS Secrets Manager 是比 SSM Parameter store 更新的服务. https://docs.aws.amazon.com/secretsmanager/latest/userguide/create_database_secret.html
D29: {=_xlfn.LET(_xlpm.v,INDEX($B:$B, 4 + INT((ROW()-4)/13)*13 + 8), IF(_xlpm.v=0,"",_xlpm.v))} | F29: =2 -> 2 | G29: =_xlfn.XLOOKUP($F29,题库数据!$A$5:$A$104,题库数据!$J$5:$J$104,"") -> C | H29: =_xlfn.LET(_xlpm.v,_xlfn.XLOOKUP(F29,题库数据!$A$5:$A$104,题库数据!$K$5:$K$104,""),IF(OR(_xlpm.v="",_xlpm.v=0),"",_xlpm.v)) -> AWS Secrets Manager 是比 SSM Parameter store 更新的服务. https://docs.aws.amazon.com/secretsmanager/latest/userguide/create_database_secret.html
A30: 题目 3： | B30: 一家公司正在向 AWS 部署一个新的公共 Web 应用程序.该应用程序将在 Application Load Balancer (ALB)之后运行,该应用程序需要在边缘使用由外部证书颁发机构颁发的 SSL/TLS 证书进行加密(CA).证书必须在证书到期之前每年轮换.解决方案架构师应该做什么来满足这些要求? | D30: {=_xlfn.LET(_xlpm.v,INDEX($B:$B, 4 + INT((ROW()-4)/13)*13 + 8), IF(_xlpm.v=0,"",_xlpm.v))} | F30: =3 -> 3 | G30: =_xlfn.XLOOKUP($F30,题库数据!$A$5:$A$104,题库数据!$J$5:$J$104,"") -> D | H30: =_xlfn.LET(_xlpm.v,_xlfn.XLOOKUP(F30,题库数据!$A$5:$A$104,题库数据!$K$5:$K$104,""),IF(OR(_xlpm.v="",_xlpm.v=0),"",_xlpm.v)) -> It's a third-party certificate, hence AWS cannot manage renewal automatically. The closest thing you can do is to send a notification to renew the 3rd party certificate.
D31: {=_xlfn.LET(_xlpm.v,INDEX($B:$B, 4 + INT((ROW()-4)/13)*13 + 8), IF(_xlpm.v=0,"",_xlpm.v))} | F31: =3 -> 3 | G31: =_xlfn.XLOOKUP($F31,题库数据!$A$5:$A$104,题库数据!$J$5:$J$104,"") -> D | H31: =_xlfn.LET(_xlpm.v,_xlfn.XLOOKUP(F31,题库数据!$A$5:$A$104,题库数据!$K$5:$K$104,""),IF(OR(_xlpm.v="",_xlpm.v=0),"",_xlpm.v)) -> It's a third-party certificate, hence AWS cannot manage renewal automatically. The closest thing you can do is to send a notification to renew the 3rd party certificate.
A32: A: | B32: =_xlfn.XLOOKUP($F32,题库[题号],题库[选项A]) -> 使用 AWS Certificate Manager (ACM) 颁发 SSL/TLS 证书.将证书应用到 ALB.使用托管续订功能自动轮换证书. | D32: {=_xlfn.LET(_xlpm.v,INDEX($B:$B, 4 + INT((ROW()-4)/13)*13 + 8), IF(_xlpm.v=0,"",_xlpm.v))} | F32: =3 -> 3 | G32: =_xlfn.XLOOKUP($F32,题库数据!$A$5:$A$104,题库数据!$J$5:$J$104,"") -> D | H32: =_xlfn.LET(_xlpm.v,_xlfn.XLOOKUP(F32,题库数据!$A$5:$A$104,题库数据!$K$5:$K$104,""),IF(OR(_xlpm.v="",_xlpm.v=0),"",_xlpm.v)) -> It's a third-party certificate, hence AWS cannot manage renewal automatically. The closest thing you can do is to send a notification to renew the 3rd party certificate.
A33: B: | B33: =_xlfn.XLOOKUP($F33,题库[题号],题库[选项B]) -> 使用 AWS Certificate Manager (ACM)颁发 SSL/TLS 证书.从证书中导入密钥材料.将证书应用到 ALB.使用托管续订功能自动轮换证书. | D33: {=_xlfn.LET(_xlpm.v,INDEX($B:$B, 4 + INT((ROW()-4)/13)*13 + 8), IF(_xlpm.v=0,"",_xlpm.v))} | F33: =3 -> 3 | G33: =_xlfn.XLOOKUP($F33,题库数据!$A$5:$A$104,题库数据!$J$5:$J$104,"") -> D | H33: =_xlfn.LET(_xlpm.v,_xlfn.XLOOKUP(F33,题库数据!$A$5:$A$104,题库数据!$K$5:$K$104,""),IF(OR(_xlpm.v="",_xlpm.v=0),"",_xlpm.v)) -> It's a third-party certificate, hence AWS cannot manage renewal automatically. The closest thing you can do is to send a notification to renew the 3rd party certificate.
A34: C: | B34: =_xlfn.XLOOKUP($F34,题库[题号],题库[选项C]) -> 使用 AWS Certificate Manager (ACM) 私有证书颁发机构从根 CA 颁发 SSL/TLS 证书.将证书应用到 ALB.使用托管续订功能自动轮换证书. | D34: {=_xlfn.LET(_xlpm.v,INDEX($B:$B, 4 + INT((ROW()-4)/13)*13 + 8), IF(_xlpm.v=0,"",_xlpm.v))} | F34: =3 -> 3 | G34: =_xlfn.XLOOKUP($F34,题库数据!$A$5:$A$104,题库数据!$J$5:$J$104,"") -> D | H34: =_xlfn.LET(_xlpm.v,_xlfn.XLOOKUP(F34,题库数据!$A$5:$A$104,题库数据!$K$5:$K$104,""),IF(OR(_xlpm.v="",_xlpm.v=0),"",_xlpm.v)) -> It's a third-party certificate, hence AWS cannot manage renewal automatically. The closest thing you can do is to send a notification to renew the 3rd party certificate.
A35: D: | B35: =_xlfn.XLOOKUP($F35,题库[题号],题库[选项D]) -> 使用 AWS Certificate Manager (ACM) 导入 SSL/TLS 证书.将证书应用到 ALB.使用 Amazon EventBridge (Amazon CloudWatch Events)在证书即将到期时发送通知.手动轮换证书. | D35: {=_xlfn.LET(_xlpm.v,INDEX($B:$B, 4 + INT((ROW()-4)/13)*13 + 8), IF(_xlpm.v=0,"",_xlpm.v))} | F35: =3 -> 3 | G35: =_xlfn.XLOOKUP($F35,题库数据!$A$5:$A$104,题库数据!$J$5:$J$104,"") -> D | H35: =_xlfn.LET(_xlpm.v,_xlfn.XLOOKUP(F35,题库数据!$A$5:$A$104,题库数据!$K$5:$K$104,""),IF(OR(_xlpm.v="",_xlpm.v=0),"",_xlpm.v)) -> It's a third-party certificate, hence AWS cannot manage renewal automatically. The closest thing you can do is to send a notification to renew the 3rd party certificate.
B36: =_xlfn.LET(_xlpm.v,_xlfn.XLOOKUP($F36,题库[题号],题库[选项E],""),IF(OR(_xlpm.v="",_xlpm.v=0),"",_xlpm.v)) | D36: {=_xlfn.LET(_xlpm.v,INDEX($B:$B, 4 + INT((ROW()-4)/13)*13 + 8), IF(_xlpm.v=0,"",_xlpm.v))} | F36: =3 -> 3 | G36: =_xlfn.XLOOKUP($F36,题库数据!$A$5:$A$104,题库数据!$J$5:$J$104,"") -> D | H36: =_xlfn.LET(_xlpm.v,_xlfn.XLOOKUP(F36,题库数据!$A$5:$A$104,题库数据!$K$5:$K$104,""),IF(OR(_xlpm.v="",_xlpm.v=0),"",_xlpm.v)) -> It's a third-party certificate, hence AWS cannot manage renewal automatically. The closest thing you can do is to send a notification to renew the 3rd party certificate.
B37: =_xlfn.LET(_xlpm.v,_xlfn.XLOOKUP($F37,题库[题号],题库[选项F],""),IF(OR(_xlpm.v="",_xlpm.v=0),"",_xlpm.v)) | D37: {=_xlfn.LET(_xlpm.v,INDEX($B:$B, 4 + INT((ROW()-4)/13)*13 + 8), IF(_xlpm.v=0,"",_xlpm.v))} | F37: =3 -> 3 | G37: =_xlfn.XLOOKUP($F37,题库数据!$A$5:$A$104,题库数据!$J$5:$J$104,"") -> D | H37: =_xlfn.LET(_xlpm.v,_xlfn.XLOOKUP(F37,题库数据!$A$5:$A$104,题库数据!$K$5:$K$104,""),IF(OR(_xlpm.v="",_xlpm.v=0),"",_xlpm.v)) -> It's a third-party certificate, hence AWS cannot manage renewal automatically. The closest thing you can do is to send a notification to renew the 3rd party certificate.
A38: 你的答案 | D38: {=_xlfn.LET(_xlpm.v,INDEX($B:$B, 4 + INT((ROW()-4)/13)*13 + 8), IF(_xlpm.v=0,"",_xlpm.v))} | F38: =3 -> 3 | G38: =_xlfn.XLOOKUP($F38,题库数据!$A$5:$A$104,题库数据!$J$5:$J$104,"") -> D | H38: =_xlfn.LET(_xlpm.v,_xlfn.XLOOKUP(F38,题库数据!$A$5:$A$104,题库数据!$K$5:$K$104,""),IF(OR(_xlpm.v="",_xlpm.v=0),"",_xlpm.v)) -> It's a third-party certificate, hence AWS cannot manage renewal automatically. The closest thing you can do is to send a notification to renew the 3rd party certificate.
A39: 结果 | B39: =_xlfn.LET(_xlpm.inp,$B$38,_xlpm.nInp,_xlfn.LET(_xlpm.raw,UPPER(TRIM($B$38)),_xlpm.clean,SUBSTITUTE(SUBSTITUTE(SUBSTITUTE(SUBSTITUTE(SUBSTITUTE(_xlpm.raw,"，",","),"、",","),"；",",")," ",""),",",""),_xlfn.TEXTJOIN(",",TRUE,IF(ISNUMBER(SEARCH("A",_xlpm.clean)),"A",""),IF(ISNUMBER(SEARCH("B",_xlpm.clean)),"B",""),IF(ISNUMBER(SEARCH("C",_xlpm.clean)),"C",""),IF(ISNUMBER(SEARCH("D",_xlpm.clean)),"D",""),IF(ISNUMBER(SEARCH("E",_xlpm.clean)),"E",""),IF(ISNUMBER(SEARCH("F",_xlpm.clean)),"F",""))),_xlpm.nStd,_xlfn.LET(_xlpm.raw,UPPER(TRIM($G$30)),_xlpm.clean,SUBSTITUTE(SUBSTITUTE(SUBSTITUTE(SUBSTITUTE(SUBSTITUTE(_xlpm.raw,"，",","),"、",","),"；",",")," ",""),",",""),_xlfn.TEXTJOIN(",",TRUE,IF(ISNUMBER(SEARCH("A",_xlpm.clean)),"A",""),IF(ISNUMBER(SEARCH("B",_xlpm.clean)),"B",""),IF(ISNUMBER(SEARCH("C",_xlpm.clean)),"C",""),IF(ISNUMBER(SEARCH("D",_xlpm.clean)),"D",""),IF(ISNUMBER(SEARCH("E",_xlpm.clean)),"E",""),IF(ISNUMBER(SEARCH("F",_xlpm.clean)),"F",""))),IF(LEN(TRIM(_xlpm.inp))=0,"",IF(AND(_xlpm.nInp<>"",_xlpm.nStd<>"",_xlpm.nInp=_xlpm.nStd),"✅正确","❌错误"))) | D39: {=_xlfn.LET(_xlpm.v,INDEX($B:$B, 4 + INT((ROW()-4)/13)*13 + 8), IF(_xlpm.v=0,"",_xlpm.v))} | F39: =3 -> 3 | G39: =_xlfn.XLOOKUP($F39,题库数据!$A$5:$A$104,题库数据!$J$5:$J$104,"") -> D | H39: =_xlfn.LET(_xlpm.v,_xlfn.XLOOKUP(F39,题库数据!$A$5:$A$104,题库数据!$K$5:$K$104,""),IF(OR(_xlpm.v="",_xlpm.v=0),"",_xlpm.v)) -> It's a third-party certificate, hence AWS cannot manage renewal automatically. The closest thing you can do is to send a notification to renew the 3rd party certificate.
A40: 正确答案 | B40: =_xlfn.LET(_xlpm.inp,$B$38,_xlpm.nStd,_xlfn.LET(_xlpm.raw,UPPER(TRIM($G$30)),_xlpm.clean,SUBSTITUTE(SUBSTITUTE(SUBSTITUTE(SUBSTITUTE(SUBSTITUTE(_xlpm.raw,"，",","),"、",","),"；",",")," ",""),",",""),_xlfn.TEXTJOIN(",",TRUE,IF(ISNUMBER(SEARCH("A",_xlpm.clean)),"A",""),IF(ISNUMBER(SEARCH("B",_xlpm.clean)),"B",""),IF(ISNUMBER(SEARCH("C",_xlpm.clean)),"C",""),IF(ISNUMBER(SEARCH("D",_xlpm.clean)),"D",""),IF(ISNUMBER(SEARCH("E",_xlpm.clean)),"E",""),IF(ISNUMBER(SEARCH("F",_xlpm.clean)),"F",""))),IF(OR(LEN(TRIM(_xlpm.inp))=0,_xlpm.nStd=""),"",_xlpm.nStd)) | D40: {=_xlfn.LET(_xlpm.v,INDEX($B:$B, 4 + INT((ROW()-4)/13)*13 + 8), IF(_xlpm.v=0,"",_xlpm.v))} | F40: =3 -> 3 | G40: =_xlfn.XLOOKUP($F40,题库数据!$A$5:$A$104,题库数据!$J$5:$J$104,"") -> D | H40: =_xlfn.LET(_xlpm.v,_xlfn.XLOOKUP(F40,题库数据!$A$5:$A$104,题库数据!$K$5:$K$104,""),IF(OR(_xlpm.v="",_xlpm.v=0),"",_xlpm.v)) -> It's a third-party certificate, hence AWS cannot manage renewal automatically. The closest thing you can do is to send a notification to renew the 3rd party certificate.
...

Sheet 101-200
A1: 📘 AWS-SAA-C03 顺序刷题（101-200）
A2: 在每题「你的答案」输入 A 或 C,D（英文逗号）后，才会显示：结果 / 正确答案 / 解析，并自动对选项标色（绿=正确，红=你选错）。
A3: {=_xlfn.LET(_xlpm.ans,SUMPRODUCT(($A$4:$A$1304="你的答案")*($B$4:$B$1304<>"")),_xlpm.corr,SUMPRODUCT(($A$4:$A$1304="结果")*($B$4:$B$1304="✅正确")),_xlpm.total,100,_xlpm.rate,IF(_xlpm.ans=0,0,_xlpm.corr/_xlpm.ans),"📊 进度：已作答 "&_xlpm.ans&"/"&_xlpm.total&" | 正确 "&_xlpm.corr&" | 正确率 "&TEXT(_xlpm.rate,"0.0%"))} -> 📊 进度：已作答 0/100 | 正确 0 | 正确率 0.0%
A4: 题目 101： | B4: Q101 一家公司在多个大洲的城市收集温度.湿度和大气压力数据.每个站点每天收集的平均数据量为 500 GB.每个站点都有高速互联网连接.该公司的天气预报应用程序基于在单个区域并每天分析数据.从所有这些全球站点汇总数据的最快方法是什么? | F4: 101 | G4: A | H4: 您可能出于各种原因想要在存储桶上使用 Transfer Acceleration,包括以下原因 :- 您的客户从世界各地上传到集中式存储桶 .您定期跨大陆传输 GB 到 TB 的数据 .- 上传到 Amazon S3 时,您无法利用 Internet 上的所有可用带宽. https://docs.aws.amazon.com/AmazonS3/latest/dev/transfer-acceleration.html https://aws.amazon.com/s3/transferacceleration/#:~:text=S3%20Transfer%20Acceleration%20(S3TA)%20reduces,to%20S3%20for%20remote%20applications Amazon S3 Transfer Acceleration 可以加快内容传输到和对于大型对象的长距离传输,从 Amazon S3 中节省多达 50-500%.拥有广泛用户的 Web 或移动应用程序或托管在远离其 S3 存储桶的应用程序的客户可以体验到较长且可变的上传和下载速度互联网 https://docs.aws.amazon.com/AmazonS3/latest/userguide/mpuoverview.html 提高吞吐量 - 您可以并行上传部分以提高吞吐量.
A6: A: | B6: 在目标存储桶上启用 Amazon S3 Transfer Acceleration.使用分段上传将站点数据直接上传到目标存储桶. | F6: 101 | G6: A | H6: 您可能出于各种原因想要在存储桶上使用 Transfer Acceleration,包括以下原因 :- 您的客户从世界各地上传到集中式存储桶 .您定期跨大陆传输 GB 到 TB 的数据 .- 上传到 Amazon S3 时,您无法利用 Internet 上的所有可用带宽. https://docs.aws.amazon.com/AmazonS3/latest/dev/transfer-acceleration.html https://aws.amazon.com/s3/transferacceleration/#:~:text=S3%20Transfer%20Acceleration%20(S3TA)%20reduces,to%20S3%20for%20remote%20applications Amazon S3 Transfer Acceleration 可以加快内容传输到和对于大型对象的长距离传输,从 Amazon S3 中节省多达 50-500%.拥有广泛用户的 Web 或移动应用程序或托管在远离其 S3 存储桶的应用程序的客户可以体验到较长且可变的上传和下载速度互联网 https://docs.aws.amazon.com/AmazonS3/latest/userguide/mpuoverview.html 提高吞吐量 - 您可以并行上传部分以提高吞吐量.
